Workbook

Sheet Índice
B3: ÍNDICE
K7: Página | AA7: 42491
C8: Garantia e Prazo de Fabricação | K8: 01 | AA8: 160
C9: Limpeza e Conservação | K9: 02
C10: Assitência Técnica | K10: 03
C11: Cortina Rolô | K11: 06 | AA11: 192
C12: Linha Premium | K12: 09 | AA12: 140.5
C13: Cortina Romana | K13: 12 | AA13: 169
C14: Cortina Painel | K14: 14 | AA14: 132.4
C15: Cortina de Teto | K15: 16 | AA15: 159
C16: Coleção Soltis (Ferrari ®) | K16: 18
C17: Persiana Vertical | K17: 19 | AA17: 160
C18: Persiana Horizontal de Alumínio | K18: 22 | AA18: 160
C19: Persiana Horizontal de Madeira - Bambu - Sintética - PVC Curve | K19: 25 | AA19: 160
C20: Cortina Celular e Vert Gliss | K20: 27 | AA20: 153.4
C21: Cortina Plissada | K21: 29 | AA21: 153.4
C22: Motorização Amorim | K22: 33 | AA22: 130.1
C23: Motorização Somfy | K23: 37 | AA23: 179.3
AA24: 179.3
AA25: 103.3
AA26: 120.4
AA28: 105.3
AA29: 116.5
AA31: 132.4
AA32: 132.4
AA33: 126.5
AA34: 126.2
AA35: 132.4
AA36: 144.7
AA37: 130.1
... AA58: 111.8
B63: ACESSE NOSSO SITE
B64: www.amorimcortinas.com.br

Sheet Info
K2: Página - 1 | L2: =Rolô!L2 -> 2026 - v.03
B3: GARANTIA E PRAZO DE FABRICAÇÃO
C6: As Cortinas e Persianas Amorim são produtos personalizados, fabricados somente sob encomenda e com medidas especificadas pela revenda. O prazo de garantia é contado a partir da data de entrega do produto ao revendedor. | AA6: 42491
AA7: 160
AA8: 192
C9: Os produtos Amorim possuem 3 anos de garantia, somente para cobertura por defeito originado por falha oculta de fabricação. | AA9: 140.5
AA10: 169
C11: Motores para cortinas e persianas possuem 5 anos de garantia, somente para cobertura por defeito originado por falha oculta de fabricação. | AA11: 132.4
AA12: 159
C13: Acessórios: fonte, receptor e controle possuem 2 anos de garantia, somente para cobertura por defeito originado por falha oculta de fabricação. | AA13: 160
AA14: 160
AA15: 160
AA17: 153.4
B18: PARA MAIS INFORMAÇÕES, SOLICITE O TERMO DE GARANTIA. | AA18: 179.3
B19: PRAZO DE FABRICAÇÃO | AA19: 120.4
C20: Cortina Rolô: 5 dias úteis *ACIMA DE 50 PEÇAS (PRAZO SOB CONSULTA) | AA20: 105.3
C21: Cortina Rolô Motorizada: 5 dias úteis | AA21: 105.3
C22: Cortina Rolô Motorizada: 5 dias úteis | AA22: 116.5
AA23: 132.4
C24: Linha Premium: 10 dias úteis | AA24: 132.4
C25: Passione/ Vert Gliss: 15 dias úteis | AA25: 132.4
C26: Cortina Atena: 5 dias úteis | AA26: 126.5
AA27: 126.2
C28: Cortina Romana (Manual e Motorizada): 7 dias úteis | AA28: 132.4
C29: Cortina Romana Classic (Manual e Motorizada): 10 dias úteis | AA29: 144.7
AA31: 117.9
C32: Cortina Painel Europa: 7 dias úteis | AA32: 111.8
AA33: 137.5
AA34: 125
C35: Cortina de Teto Allure Manual e Monocontrole: 10 dias úteis | AA35: 125
C36: Cortina de Teto Allure Motorizado: 15 dias úteis
AA37: 110.6
C38: Persiana Vertical Tecido e PVC: 5 dias úteis ** | AA38: 125
C39: Persiana Vertical Tecido e PVC com galeria de madeira: 10 dias úteis ** | AA39: 110.6
C40: Persiana Vertical Tecido Motorizada : 5 dias úteis ** | AA40: 116.1
C41: **ACIMA DE 50 PEÇAS (PRAZO SOB CONSULTA) | AA41: 160
AA42: 144.7
C43: Persiana Horizontal de Alumínio 16mm e 25mm Standard e Entre Vidros: 5 dias úteis | AA43: 126.2
C44: Persiana Horizontal de Alumínio 16mm e 25mm Comando Único, Monocontrole e Motorizada: 7 dias úteis | AA44: 160.3
C45: Persiana Horizontal de Alumínio 50mm Standard e Monocontrole: 7 dias úteis | AA45: 139.1
...

Sheet Assistência Técnica
K2: Página 3 - | L2: =Rolô!L2 -> 2026 - v.03 | N2: * DIGITE A PORCENTAGEM PARA MARKUP
B3: ASSISTÊNCIA TÉCNICA | N3: 0
B6: SERVIÇOS - CORTINA ROLÔ
B7: ITEM | C7: DESCRIÇÃO | J7: VALOR À VISTA (R$) | AA7: 43009 | AB7: 43258 | AC7: 43862 | AD7: 43952 | AE7: 44136
B8: 1 | C8: CORTE NA ALTURA DA CORTINA ROLÔ | J8: =ROUNDUP(((AH8*$N$3)+AH8),1) -> 53.3 | AA8: 33 | AB8: =AA8*1.1 -> 36.3 | AC8: =AB8*1.1 -> 39.93 | AD8: 43.923 | AE8: 48.4 | AH8: =AE8*1.1 -> 53.24
B9: 2 | C9: CORTE NA LARGURA DA CORTINA ROLÔ | J9: =ROUNDUP(((AH9*$N$3)+AH9),1) -> 101.6 | AA9: 66 | AB9: =AA9*1.1 -> 72.6 | AC9: =AB9*1.05 -> 76.23 | AD9: 83.853 | AE9: 92.3 | AH9: =AE9*1.1 -> 101.53
B10: 3 | C10: TROCA DE COMANDO DE CORTINA ROLÔ (VALOR DE MÃO DE OBRA, COMANDO SERÁ COBRADO SEPARADAMENTE) | J10: =ROUNDUP(((AH10*$N$3)+AH10),1) -> 35.6 | AA10: 22 | AB10: =AA10*1.1 -> 24.2 | AC10: =AB10*1.1 -> 26.62 | AD10: 29.282 | AE10: 32.3 | AH10: =AE10*1.1 -> 35.53
B11: 4 | AH11: =AE11*1.1 -> 0
B12: 5 | C12: TROCA DE TECIDO (VALOR DE MÃO DE OBRA, TECIDO SERÁ COBRADO SEPARADAMENTE) | J12: =ROUNDUP(((AH12*$N$3)+AH12),1) -> 35.6 | AA12: 22 | AB12: =AA12*1.1 -> 24.2 | AC12: =AB12*1.1 -> 26.62 | AD12: 29.282 | AE12: 32.3 | AH12: =AE12*1.1 -> 35.53
B13: 6 | C13: CORTE DE TRILHO DE CORRER PARA ROLÔ (TRILHO DEVE SER SOLICIDADO SEPARADAMENTE) | J13: =ROUNDUP(((AH13*$N$3)+AH13),1) -> 53.3 | AA13: 33 | AB13: =AA13*1.1 -> 36.3 | AC13: =AB13*1.1 -> 39.93 | AD13: 43.923 | AE13: 48.4 | AH13: =AE13*1.1 -> 53.24
B14: 7 | C14: CORTE DE BANDÔ OU BARRA NIVELADORA | J14: =ROUNDUP(((AH14*$N$3)+AH14),1) -> 35.6 | AA14: 22 | AB14: =AA14*1.1 -> 24.2 | AC14: =AB14*1.1 -> 26.62 | AD14: 29.282 | AE14: 32.3 | AH14: =AE14*1.1 -> 35.53
B15: 8 | C15: TROCA DE TUBO (VALOR DE MÃO DE OBRA, TUBO SERÁ COBRADO SEPARADAMENTE) | J15: =ROUNDUP(((AH15*$N$3)+AH15),1) -> 35.6 | AA15: 22 | AB15: =AA15*1.1 -> 24.2 | AC15: =AB15*1.1 -> 26.62 | AD15: 29.282 | AE15: 32.3 | AH15: =AE15*1.1 -> 35.53
B16: 9 | C16: REGULAGEM PEÇA MANUAL | J16: =ROUNDUP(((AH16*$N$3)+AH16),1) -> 26.7 | AA16: 16.5 | AB16: =AA16*1.1 -> 18.15 | AC16: =AB16*1.1 -> 19.965 | AD16: 21.9615 | AE16: 24.2 | AH16: =AE16*1.1 -> 26.62
B17: 10 | C17: REGULAGEM PEÇA MOTORIZADA | J17: =ROUNDUP(((AH17*$N$3)+AH17),1) -> 54.5 | AE17: 49.5 | AH17: =AE17*1.1 -> 54.45
B18: 11 | C18: INVESÃO DE ROLAMENTO | J18: =ROUNDUP(((AH18*$N$3)+AH18),1) -> 35.6 | AA18: 22 | AB18: =AA18*1.1 -> 24.2 | AC18: =AB18*1.1 -> 26.62 | AD18: 29.282 | AE18: 32.3 | AH18: =AE18*1.1 -> 35.53
B19: 12 | C19: MOTORIZAÇÃO (VALOR DE MÃO DE OBRA, MOTORIZAÇÃO COBRADA SEPARADAMENTE) | J19: =ROUNDUP(((AH19*$N$3)+AH19),1) -> 60.5 | AA19: 22 | AB19: =AA19*1.1 -> 24.2 | AC19: =AB19*1.1 -> 26.62 | AD19: 29.282 | AE19: 55 | AH19: =AE19*1.1 -> 60.5
B20: 13 | C20: TROCA DE BANDÔ OU BASE (VALOR DE MÃO DE OBRA, BANDÔ OU BASE SERÁ COBRADO SEPARADAMENTE) | J20: =ROUNDUP(((AH20*$N$3)+AH20),1) -> 35.6 | AA20: 27.9 | AB20: =AA20*1.1 -> 30.69 | AC20: =AB20*1.1 -> 33.759 | AD20: 37.1349 | AE20: 32.3 | AH20: =AE20*1.1 -> 35.53
B21: 14 | AH21: =AE21*1.1 -> 0
B22: SERVIÇOS - CORTINA ETERNITY, ETERNITY LINE, GALAXY, ILLUMINÊ, INFINITY, LUMIÉRE E MELÍADE | AH22: =AE22*1.1 -> 0
B23: ITEM | C23: DESCRIÇÃO | J23: VALOR À VISTA (R$) | AH23: =AE23*1.1 -> 0
B24: 15 | C24: CORTE NA ALTURA | J24: =ROUNDUP(((AH24*$N$3)+AH24),1) -> 88.8 | AA24: 55 | AB24: =AA24*1.1 -> 60.5 | AC24: =AB24*1.1 -> 66.55 | AD24: 73.205 | AE24: 80.7 | AH24: =AE24*1.1 -> 88.77
B25: 16 | C25: CORTE NA LARGURA | J25: =ROUNDUP(((AH25*$N$3)+AH25),1) -> 203.1 | AA25: 132 | AB25: =AA25*1.1 -> 145.2 | AC25: =AB25*1.05 -> 152.46 | AD25: 167.706 | AE25: 184.58 | AH25: =AE25*1.1 -> 203.038
B26: 17 | C26: TROCA DE COMANDO (VALOR DE MÃO DE OBRA, COMANDO SERÁ COBRADO SEPARADAMENTE) | J26: =ROUNDUP(((AH26*$N$3)+AH26),1) -> 67.3 | AA26: 41.7 | AB26: =AA26*1.1 -> 45.87 | AC26: =AB26*1.1 -> 50.457 | AD26: 55.5027 | AE26: 61.16 | AH26: =AE26*1.1 -> 67.276
B27: 18 | C27: TROCA DE TECIDO (VALOR DE MÃO DE OBRA, TECIDO SERÁ COBRADO SEPARADAMENTE) | J27: =ROUNDUP(((AH27*$N$3)+AH27),1) -> 88.8 | AA27: 55 | AB27: =AA27*1.1 -> 60.5 | AC27: =AB27*1.1 -> 66.55 | AD27: 73.205 | AE27: 80.7 | AH27: =AE27*1.1 -> 88.77
B28: 19 | C28: CORTE DE BANDÔ OU BARRA NIVELADORA | J28: =ROUNDUP(((AH28*$N$3)+AH28),1) -> 35.5 | AA28: 22 | AB28: =AA28*1.1 -> 24.2 | AC28: =AB28*1.1 -> 26.62 | AD28: 29.282 | AE28: 32.23 | AH28: =AE28*1.1 -> 35.453
B29: 20 | C29: MOTORIZAÇÃO (VALOR DE MÃO DE OBRA, MOTORIZAÇÃO COBRADA SEPARADAMENTE) | J29: =ROUNDUP(((AH29*$N$3)+AH29),1) -> 60.5 | AA29: 16.5 | AB29: =AA29*1.1 -> 18.15 | AC29: =AB29*1.1 -> 19.965 | AD29: 21.9615 | AE29: 55 | AH29: =AE29*1.1 -> 60.5
B30: 21 | C30: REGULAGEM PEÇA MANUAL | J30: =ROUNDUP(((AH30*$N$3)+AH30),1) -> 26.7 | AE30: 24.2 | AH30: =AE30*1.1 -> 26.62
B31: 22 | C31: REGULAGEM PEÇA MOTORIZADA | J31: =ROUNDUP(((AH31*$N$3)+AH31),1) -> 54.5 | AE31: 49.5 | AH31: =AE31*1.1 -> 54.45
B32: 23 | C32: TROCA DE BANDÔ, BARRA NIVELADORA OU BASE (VALOR DE MÃO DE OBRA, BANDÔ, BARRA OU BASE SERÃO COBRADOS SEPARADAMENTE) | J32: =ROUNDUP(((AH32*$N$3)+AH32),1) -> 35.6 | AA32: 22 | AB32: =AA32*1.1 -> 24.2 | AC32: =AB32*1.1 -> 26.62 | AD32: 29.282 | AE32: 32.3 | AH32: =AE32*1.1 -> 35.53
B33: 24
B34: SERVIÇOS - CORTINA ROLÔ STILLO | AH34: =AE34*1.1 -> 0
B35: ITEM | C35: DESCRIÇÃO | J35: VALOR À VISTA (R$) | AH35: =AE35*1.1 -> 0
B36: 25 | C36: CORTE NA ALTURA | J36: =ROUNDUP(((AH36*$N$3)+AH36),1) -> 124.1 | AA36: 77 | AB36: =AA36*1.1 -> 84.7 | AC36: =AB36*1.1 -> 93.17 | AD36: 102.487 | AE36: 112.8 | AH36: =AE36*1.1 -> 124.08
B37: 26 | C37: CORTE NA LARGURA | J37: =ROUNDUP(((AH37*$N$3)+AH37),1) -> 152.3 | AA37: 99 | AB37: =AA37*1.1 -> 108.9 | AC37: =AB37*1.05 -> 114.345 | AD37: 125.7795 | AE37: 138.4 | AH37: =AE37*1.1 -> 152.24
B38: 27 | C38: TROCA DE COMANDO (VALOR DE MÃO DE OBRA, COMANDO SERÁ COBRADO SEPARADAMENTE) | J38: =ROUNDUP(((AH38*$N$3)+AH38),1) -> 63 | AA38: 39 | AB38: =AA38*1.1 -> 42.9 | AC38: =AB38*1.1 -> 47.19 | AD38: 51.909 | AE38: 57.2 | AH38: =AE38*1.1 -> 62.92
B39: 28 | C39: TROCA DE TECIDO (VALOR DE MÃO DE OBRA, TECIDO SERÁ COBRADO SEPARADAMENTE) | J39: =ROUNDUP(((AH39*$N$3)+AH39),1) -> 88.8 | AA39: 55 | AB39: =AA39*1.1 -> 60.5 | AC39: =AB39*1.1 -> 66.55 | AD39: 73.205 | AE39: 80.7 | AH39: =AE39*1.1 -> 88.77
B40: 29 | C40: CORTE DE BANDÔ OU BARRA NIVELADORA | J40: =ROUNDUP(((AH40*$N$3)+AH40),1) -> 35.6 | AA40: 22 | AB40: =AA40*1.1 -> 24.2 | AC40: =AB40*1.1 -> 26.62 | AD40: 29.282 | AE40: 32.3 | AH40: =AE40*1.1 -> 35.53
B41: 30 | C41: REGULAGEM PEÇA MANUAL | J41: =ROUNDUP(((AH41*$N$3)+AH41),1) -> 26.7 | AE41: 24.2 | AH41: =AE41*1.1 -> 26.62
B42: 31 | C42: REGULAGEM PEÇA MOTORIZADA | J42: =ROUNDUP(((AH42*$N$3)+AH42),1) -> 54.5 | AA42: 16.5 | AB42: =AA42*1.1 -> 18.15 | AC42: =AB42*1.1 -> 19.965 | AD42: 21.9615 | AE42: 49.5 | AH42: =AE42*1.1 -> 54.45
B43: 32 | C43: INVERSÃO DE ROLAMENTO | J43: =ROUNDUP(((AH43*$N$3)+AH43),1) -> 35.6 | AE43: 32.3 | AH43: =AE43*1.1 -> 35.53
...

Sheet Rolô
K2: Página 6 - | L2: 2026 - v.03 | N2: * DIGITE A PORCENTAGEM PARA MARKUP
N3: 0
B4: PRODUTO EM CONFORMIDADE COM A NORMA ABNT NBR 16234: 2014
B6: ITEM | C6: COLEÇÃO | E6: COR | H6: LAR. MAX. | I6: VALOR À VISTA (R$)/M² | K6: IPI | AA6: 42491 | AB6: 43026 | AC6: 43258 | AE6: 43862 | AH6: 43952 | AI6: 44105 | AJ6: 44256 | AK6: 44287 | AL6: 44317 | AM6: 44348 | AN6: 44378 | AO6: 44501 | AS6: 44682 | AT6: 45383 | BI6: 45658
B7: 1 | C7: SCREEN 1% | E7: 0001, 0005 e 0006, 1010, 1030 e 1031 | H7: 3 | I7: =ROUNDUP(((BJ7*$N$3)+BJ7),1) -> 166.6 | K7: 0 | AA7: 160 | AB7: 160 | AC7: =AB7*1.1 -> 176 | AE7: =AC7*1.06 -> 186.56 | AH7: =AE7*1.1 -> 205.216 | AI7: =AH7 -> 205.216 | AJ7: =AI7 -> 205.216 | AN7: =AJ7 -> 205.216 | AO7: 205.3 | AP7: =AO7*1.06 -> 217.618 | AS7: 185 | AT7: =AS7-((AS7*10)/100) -> 166.5 | AV7: =AT7*1.07 -> 178.155 | BI7: =AV7*1.1 -> 195.9705 | BJ7: =BI7+(BI7-(BI7*1.15)) -> 166.57493
B8: 2 | AA8: 192 | AB8: 192 | AC8: =AB8*1.1 -> 211.2 | AE8: =AC8*1.06 -> 223.872 | AH8: =AE8*1.15 -> 257.4528 | AI8: =AH8*1.08 -> 278.04902 | AJ8: =AI8*1.05 -> 291.95148 | AN8: =AJ8 -> 291.95148 | AO8: 292 | AP8: =AO8*1.06 -> 309.52 | AV8: =AT8*1.07 -> 0 | BI8: =AV8*1.1 -> 0 | BJ8: =BI8+(BI8-(BI8*1.15)) -> 0
B9: 3 | C9: SCREEN 3% | E9: 3001, 3002, 3008, 3017, 3060 e 3061 | H9: 3 | I9: =ROUNDUP(((BJ9*$N$3)+BJ9),1) -> 157.6 | K9: 0 | AA9: 140.5 | AB9: 140.5 | AC9: =AB9*1.1 -> 154.55 | AE9: =AC9*1.06 -> 163.823 | AH9: =AE9 -> 163.823 | AI9: 163.9 | AJ9: =AI9 -> 163.9 | AN9: =AJ9*1.03 -> 168.817 | AO9: 168.9 | AP9: =AO9*1.06 -> 179.034 | AS9: 175 | AT9: =AS9-((AS9*10)/100) -> 157.5 | AV9: =AT9*1.07 -> 168.525 | BI9: =AV9*1.1 -> 185.3775 | BJ9: =BI9+(BI9-(BI9*1.15)) -> 157.57088
B10: 4 | E10: 3009 ao 3011, 3018 e 3019 | H10: 3 | I10: =ROUNDUP(((BJ10*$N$3)+BJ10),1) -> 201.2 | K10: 0 | AA10: 140.5 | AB10: 140.5 | AC10: =AB10*1.1 -> 154.55 | AE10: =AC10*1.06 -> 163.823 | AH10: =AE10*1.05 -> 172.01415 | AI10: =AH10 -> 172.01415 | AJ10: =AI10*1.05 -> 180.61486 | AN10: =AJ10*1.05 -> 189.6456 | AO10: 189.7 | AP10: =AO10*1.06 -> 201.082 | AS10: =AP10 -> 201.082 | AT10: =AS10 -> 201.082 | AV10: =AT10*1.07 -> 215.15774 | BI10: =AV10*1.1 -> 236.67351 | BJ10: =BI10+(BI10-(BI10*1.15)) -> 201.17249
B11: 5 | E11: 3012, 3013 | H11: 3 | I11: =ROUNDUP(((BJ11*$N$3)+BJ11),1) -> 191.7 | K11: 0 | AJ11: 180.61 | AN11: =AJ11 -> 180.61 | AO11: 180.7 | AP11: =AO11*1.06 -> 191.542 | AS11: =AP11 -> 191.542 | AT11: =AS11 -> 191.542 | AV11: =AT11*1.07 -> 204.94994 | BI11: =AV11*1.1 -> 225.44493 | BJ11: =BI11+(BI11-(BI11*1.15)) -> 191.62819
B12: 6 | E12: 3014 e 3015 | H12: 3 | I12: =ROUNDUP(((BJ12*$N$3)+BJ12),1) -> 216.3 | K12: 0 | AE12: 163.9 | AH12: =AE12*1.15 -> 188.485 | AI12: =AH12 -> 188.485 | AJ12: =AI12*1.05 -> 197.90925 | AN12: =AJ12*1.03 -> 203.84653 | AO12: 203.9 | AP12: =AO12*1.06 -> 216.134 | AS12: =AP12 -> 216.134 | AT12: =AS12 -> 216.134 | AV12: =AT12*1.07 -> 231.26338 | BI12: =AV12*1.1 -> 254.38972 | BJ12: =BI12+(BI12-(BI12*1.15)) -> 216.23126
B13: 7 | AA13: 169 | AB13: 169 | AC13: =AB13*1.1 -> 185.9 | AE13: 197.1 | AH13: =AE13*1.15 -> 226.665 | AI13: =AH13*1.08 -> 244.7982 | AJ13: =AI13*1.05 -> 257.03811 | AN13: =AJ13 -> 257.03811 | AO13: 257.1 | AP13: =AO13*1.06 -> 272.526 | AV13: =AT13*1.07 -> 0 | BI13: =AV13*1.1 -> 0 | BJ13: =BI13+(BI13-(BI13*1.15)) -> 0
B14: 8 | C14: SCREEN 5% | E14: 3070 ao 3076, 3078, 3079 | H14: 3 | I14: =ROUNDUP(((BJ14*$N$3)+BJ14),1) -> 142.6 | K14: 0 | AA14: 132.4 | AB14: 132.4 | AC14: =AB14*1.1 -> 145.64 | AE14: =AC14*1.06 -> 154.3784 | AH14: =AE14 -> 154.3784 | AI14: =AH14 -> 154.3784 | AJ14: =AI14 -> 154.3784 | AN14: =AJ14*1.03 -> 159.00975 | AO14: 159.1 | AP14: =AO14*1.06 -> 168.646 | AS14: 158.3 | AT14: =AS14-((AS14*10)/100) -> 142.47 | AV14: =AT14*1.07 -> 152.4429 | BI14: =AV14*1.1 -> 167.68719 | BJ14: =BI14+(BI14-(BI14*1.15)) -> 142.53411
B15: 9 | E15: 3096, 3097 E 3098 | H15: 2.5 | AA15: 159 | AB15: 159 | AC15: =AB15*1.1 -> 174.9 | AE15: =AC15*1.06 -> 185.394 | AH15: =AE15*1.15 -> 213.2031 | AI15: =AH15*1.08 -> 230.25935 | AJ15: =AI15*1.05 -> 241.77232 | AN15: =AJ15 -> 241.77232 | AO15: 241.8 | AP15: =AO15*1.06 -> 256.308 | AV15: =AT15*1.07 -> 0 | BI15: =AV15*1.1 -> 0 | BJ15: =BI15+(BI15-(BI15*1.15)) -> 0
B16: 10 | C16: SCREEN CRISTAL 5% | E16: 3100 | H16: 3 | I16: =ROUNDUP(((BJ16*$N$3)+BJ16),1) -> 228.6 | K16: 0 | AA16: 160 | AB16: 160 | AC16: =AB16*1.1 -> 176 | AE16: =AC16*1.06 -> 186.56 | AH16: =AE16*1.1 -> 205.216 | AI16: =AH16 -> 205.216 | AJ16: =AI16*1.05 -> 215.4768 | AN16: =AJ16 -> 215.4768 | AO16: 215.5 | AP16: =AO16*1.06 -> 228.43 | AS16: =AP16 -> 228.43 | AT16: =AS16 -> 228.43 | AV16: =AT16*1.07 -> 244.4201 | BI16: =AV16*1.1 -> 268.86211 | BJ16: =BI16+(BI16-(BI16*1.15)) -> 228.53279
B17: 11 | C17: SCREEN RÚSTICO 3% | E17: 3150 e 3151 | H17: 3 | I17: =ROUNDUP(((BJ17*$N$3)+BJ17),1) -> 219.1 | K17: 0 | AA17: 153.4 | AB17: 153.4 | AC17: =AB17*1.1 -> 168.74 | AE17: =AC17*1.06 -> 178.8644 | AH17: =AE17*1.1 -> 196.75084 | AI17: =AH17 -> 196.75084 | AJ17: =AI17*1.05 -> 206.58838 | AN17: =AJ17 -> 206.58838 | AO17: 206.6 | AP17: =AO17*1.06 -> 218.996 | AS17: =AP17 -> 218.996 | AT17: =AS17 -> 218.996 | AV17: =AT17*1.07 -> 234.32572 | BI17: =AV17*1.1 -> 257.75829 | BJ17: =BI17+(BI17-(BI17*1.15)) -> 219.09455
B18: 12 | C18: SCREEN RÚSTICO 5% | E18: 3155 e 3156 | H18: 3 | I18: =ROUNDUP(((BJ18*$N$3)+BJ18),1) -> 241.1 | K18: 0 | AI18: 206.59 | AJ18: =AI18*1.1 -> 227.249 | AN18: =AJ18 -> 227.249 | AO18: 227.3 | AP18: =AO18*1.06 -> 240.938 | AS18: =AP18 -> 240.938 | AT18: =AS18 -> 240.938 | AV18: =AT18*1.07 -> 257.80366 | BI18: =AV18*1.1 -> 283.58403 | BJ18: =BI18+(BI18-(BI18*1.15)) -> 241.04642
B19: 13 | E19: 3159, 3160, 3161, 3162 e 3163 | H19: 2.5 | I19: =ROUNDUP(((BJ19*$N$3)+BJ19),1) -> 209.2 | K19: 0 | AE19: =#REF! -> #REF! | AH19: =AE19 -> #REF! | AI19: =AH19*1.05 -> #REF! | AJ19: =AI19*1.05 -> #REF! | AN19: =AJ19 -> #REF! | AO19: 197.2 | AP19: =AO19*1.06 -> 209.032 | AS19: =AP19 -> 209.032 | AT19: =AS19 -> 209.032 | AV19: =AT19*1.07 -> 223.66424 | BI19: =AV19*1.1 -> 246.03066 | BJ19: =BI19+(BI19-(BI19*1.15)) -> 209.12606
B20: 14 | AA20: 179.3 | AB20: 179.3 | AC20: =AB20*1.1 -> 197.23 | AE20: =AC20*1.06 -> 209.0638 | AH20: =AE20*1.15 -> 240.42337 | AI20: =AH20*1.05 -> 252.44454 | AJ20: =AI20*1.05 -> 265.06677 | AN20: =AJ20 -> 265.06677 | AO20: 265.1 | AP20: =AO20*1.06 -> 281.006 | AS20: =AP20 -> 281.006 | AT20: =AS20 -> 281.006 | AV20: =AT20*1.07 -> 300.67642 | BI20: =AV20*1.1 -> 330.74406 | BJ20: =BI20+(BI20-(BI20*1.15)) -> 281.13245
B21: 15 | C21: SCREEN REFLEX | E21: 3121 e 3122 e 3123 | H21: 3 | I21: =ROUNDUP(((BJ21*$N$3)+BJ21),1) -> 256.2 | K21: 0 | AA21: 179.3 | AB21: 179.3 | AC21: =AB21*1.1 -> 197.23 | AE21: =AC21*1.06 -> 209.0638 | AH21: =AE21*1.05 -> 219.51699 | AI21: =AH21 -> 219.51699 | AJ21: =AI21*1.1 -> 241.46869 | AN21: =AJ21 -> 241.46869 | AO21: 241.5 | AP21: =AO21*1.06 -> 255.99 | AS21: =AP21 -> 255.99 | AT21: =AS21 -> 255.99 | AV21: =AT21*1.07 -> 273.9093 | BI21: =AV21*1.1 -> 301.30023 | BJ21: =BI21+(BI21-(BI21*1.15)) -> 256.1052
B22: 16 | C22: SCREEN BK | E22: 3200, 3201 e 3203 | H22: 2.5 | I22: =ROUNDUP(((BJ22*$N$3)+BJ22),1) -> 230.7 | K22: 0 | AS22: 281.1 | AT22: =AS22-((AS22*18)/100) -> 230.502 | AV22: =AT22*1.07 -> 246.63714 | BI22: =AV22*1.1 -> 271.30085 | BJ22: =BI22+(BI22-(BI22*1.15)) -> 230.60573
B23: 17 | C23: IBIZA | E23: 3350, 3351 e 3353 | H23: 2.6 | I23: =ROUNDUP(((BJ23*$N$3)+BJ23),1) -> 153.5 | K23: 0 | AA23: 103.3 | AB23: 111.6 | AC23: =AB23*1.1 -> 122.76 | AE23: =AC23*1.06 -> 130.1256 | AH23: =AE23*1.1 -> 143.13816 | AI23: =AH23*1.08 -> 154.58921 | AJ23: =AI23*1.1 -> 170.04813 | AN23: =AJ23 -> 170.04813 | AO23: 170.1 | AP23: =AO23*1.06 -> 180.306 | AS23: 180.4 | AT23: =AS23-((AS23*15)/100) -> 153.34 | AV23: =AT23*1.07 -> 164.0738 | BI23: =AV23*1.1 -> 180.48118 | BJ23: =BI23+(BI23-(BI23*1.15)) -> 153.409
B24: 18 | C24: BLACKOUT PINPOINT | E24: 0180 ao 0183 e 0186 ao 0190 - larg. especial 2.5 | H24: 2.5 | I24: =ROUNDUP(((BJ24*$N$3)+BJ24),1) -> 148.3 | K24: 0.1 | AA24: 120.4 | AB24: 120.4 | AC24: =AB24*1.1 -> 132.44 | AE24: =AC24*1.06 -> 140.3864 | AH24: =AE24*1.05 -> 147.40572 | AI24: =AH24*1.05 -> 154.77601 | AJ24: =AI24*1.05 -> 162.51481 | AN24: =AJ24*1.05 -> 170.64055 | AO24: 170.7 | AP24: =AO24*1.06 -> 180.942 | AS24: 164.6 | AT24: =AS24-((AS24*10)/100) -> 148.14 | AV24: =AT24*1.07 -> 158.5098 | BI24: =AV24*1.1 -> 174.36078 | BJ24: =BI24+(BI24-(BI24*1.15)) -> 148.20666
B25: 19 | AE25: 140.39 | AH25: =AE25*1.05 -> 147.4095 | AS25: =AP25 -> 0 | AT25: =AS25-((AS25*10)/100) -> 0 | AV25: =AT25*1.07 -> 0 | BI25: =AV25*1.1 -> 0 | BJ25: =BI25+(BI25-(BI25*1.15)) -> 0
B26: 20 | E26: 0180 ao 0183 e 0186, 0187 e 0190 - larg. especial 3 | H26: 3 | I26: =ROUNDUP(((BJ26*$N$3)+BJ26),1) -> 152.8 | K26: 0.1 | AE26: 140.39 | AH26: =AE26*1.1 -> 154.429 | AI26: =AH26*1.05 -> 162.15045 | AJ26: =AI26*1.05 -> 170.25797 | AN26: =AJ26*1.05 -> 178.77087 | AO26: 178.8 | AP26: =AO26*1.06 -> 189.528 | AS26: 169.7 | AT26: =AS26-((AS26*10)/100) -> 152.73 | AV26: =AT26*1.07 -> 163.4211 | BI26: =AV26*1.1 -> 179.76321 | BJ26: =BI26+(BI26-(BI26*1.15)) -> 152.79873
B27: 21 | E27: 0180 ao 0183 e 0186, 0187 e 0190 | H27: 2 | I27: =ROUNDUP(((BJ27*$N$3)+BJ27),1) -> 139.9 | K27: 0.1 | AA27: 105.3 | AB27: 105.3 | AC27: =AB27*1.1 -> 115.83 | AE27: =AC27*1.06 -> 122.7798 | AH27: =AE27*1.05 -> 128.91879 | AI27: =AH27*1.05 -> 135.36473 | AJ27: =AI27*1.1 -> 148.9012 | AN27: =AJ27*1.05 -> 156.34626 | AO27: 156.4 | AP27: =AO27*1.06 -> 165.784 | AS27: 155.3 | AT27: =AS27-((AS27*10)/100) -> 139.77 | AV27: =AT27*1.07 -> 149.5539 | BI27: =AV27*1.1 -> 164.50929 | BJ27: =BI27+(BI27-(BI27*1.15)) -> 139.8329
B28: 22 | AB28: 105.3 | AC28: =AB28*1.1 -> 115.83 | AE28: =AC28*1.06 -> 122.7798 | AH28: =AE28*1.05 -> 128.91879 | AS28: =AP28 -> 0 | AT28: =AS28-((AS28*10)/100) -> 0 | AV28: =AT28*1.07 -> 0 | BI28: =AV28*1.1 -> 0 | BJ28: =BI28+(BI28-(BI28*1.15)) -> 0
B29: 23 | C29: REQUINTE BK | E29: 0088 | H29: 2 | I29: =ROUNDUP(((BJ29*$N$3)+BJ29),1) -> 175.8 | K29: 0 | AH29: 154.2 | AI29: =AH29*1.08 -> 166.536 | AJ29: 174.79 | AN29: =AJ29*1.05 -> 183.5295 | AO29: 183.6 | AP29: =AO29*1.1 -> 201.96 | AS29: =AP29 -> 201.96 | AT29: =AS29-((AS29*13)/100) -> 175.7052 | AV29: =AT29*1.07 -> 188.00456 | BI29: =AV29*1.1 -> 206.80502 | BJ29: =BI29+(BI29-(BI29*1.15)) -> 175.78427
B30: 24 | E30: 0101, 0102, 3042, 3044, 7517 ao 7523 | H30: 3 | I30: =ROUNDUP(((BJ30*$N$3)+BJ30),1) -> 136.2 | K30: 0 | AA30: 116.5 | AB30: 125.9 | AC30: =AB30*1.1 -> 138.49 | AE30: =AC30*1.06 -> 146.7994 | AH30: =AE30 -> 146.7994 | AI30: =AH30*1.08 -> 158.54335 | AJ30: 166.23 | AN30: =AJ30*1.02 -> 169.5546 | AO30: 169.6 | AP30: =AO30*1.1 -> 186.56 | AS30: =AP30 -> 186.56 | AT30: 136.1 | AV30: =AT30*1.07 -> 145.627 | BI30: =AV30*1.1 -> 160.1897 | BJ30: =BI30+(BI30-(BI30*1.15)) -> 136.16125
B31: 25 | E31: 0103 | H31: 2.5 | I31: =ROUNDUP(((BJ31*$N$3)+BJ31),1) -> 136.2 | K31: 0 | AA31: 116.5 | AB31: 125.9 | AC31: =AB31*1.1 -> 138.49 | AE31: =AC31*1.06 -> 146.7994 | AH31: =AE31*1.05 -> 154.13937 | AI31: =AH31 -> 154.13937 | AJ31: =AI31*1.1 -> 169.55331 | AN31: =AJ31 -> 169.55331 | AO31: 169.6 | AP31: =AO31*1.06 -> 179.776 | AS31: 151.2 | AT31: =AS31-((AS31*10)/100) -> 136.08 | AV31: =AT31*1.07 -> 145.6056 | BI31: =AV31*1.1 -> 160.16616 | BJ31: =BI31+(BI31-(BI31*1.15)) -> 136.14124
B32: 26 | E32: 0105, 7511 ao 7516 | H32: 3 | I32: =ROUNDUP(((BJ32*$N$3)+BJ32),1) -> 162.3 | K32: 0 | AT32: 162.2 | AV32: =AT32*1.07 -> 173.554 | BI32: =AV32*1.1 -> 190.9094 | BJ32: =BI32+(BI32-(BI32*1.15)) -> 162.27299
B33: 27 | E33: 0106 e 0107 | H33: 2.4 | I33: =ROUNDUP(((BJ33*$N$3)+BJ33),1) -> 162.3 | K33: 0 | AA33: 116.5 | AB33: 125.9 | AC33: =AB33*1.1 -> 138.49 | AE33: =AC33*1.06 -> 146.7994 | AH33: =AE33*1.05 -> 154.13937 | AI33: =AH33 -> 154.13937 | AJ33: =AI33*1.15 -> 177.26028 | AN33: =AJ33 -> 177.26028 | AO33: 177.3 | AP33: =AO33*1.06 -> 187.938 | AS33: 162.2 | AT33: =AS33 -> 162.2 | AV33: =AT33*1.07 -> 173.554 | BI33: =AV33*1.1 -> 190.9094 | BJ33: =BI33+(BI33-(BI33*1.15)) -> 162.27299
B34: 28 | E34: 3031 | H34: 2.4 | I34: =ROUNDUP(((BJ34*$N$3)+BJ34),1) -> 204.2 | K34: 0 | AA34: 126.5 | AB34: 136.7 | AC34: =AB34*1.1 -> 150.37 | AE34: =AC34*1.06 -> 159.3922 | AH34: =AE34*1.05 -> 167.36181 | AI34: =AH34 -> 167.36181 | AJ34: =AI34*1.15 -> 192.46608 | AN34: =AJ34 -> 192.46608 | AO34: 192.5 | AP34: =AO34*1.06 -> 204.05 | AS34: =AP34 -> 204.05 | AT34: =AS34 -> 204.05 | AV34: =AT34*1.07 -> 218.3335 | BI34: =AV34*1.1 -> 240.16685 | BJ34: =BI34+(BI34-(BI34*1.15)) -> 204.14182
B35: 29 | E35: 3038 | H35: 3 | I35: =ROUNDUP(((BJ35*$N$3)+BJ35),1) -> 155.8 | K35: 0 | AA35: 132.4 | AB35: 143 | AC35: =AB35*1.1 -> 157.3 | AE35: =AC35*1.1 -> 173.03 | AH35: =AE35*1.1 -> 190.333 | AI35: =AH35*1.08 -> 205.55964 | AJ35: 226.14 | AN35: =AJ35*1.01 -> 228.4014 | AO35: 228.5 | AP35: =AO35*1.06 -> 242.21 | AS35: 207.6 | AT35: =AS35-((AS35*25)/100) -> 155.7 | AV35: =AT35*1.07 -> 166.599 | BI35: =AV35*1.1 -> 183.2589 | BJ35: =BI35+(BI35-(BI35*1.15)) -> 155.77007
B36: 30 | E36: 3037 | H36: 3 | I36: =ROUNDUP(((BJ36*$N$3)+BJ36),1) -> 155.8 | K36: 0 | AT36: 155.7 | AV36: =AT36*1.07 -> 166.599 | BI36: =AV36*1.1 -> 183.2589 | BJ36: =BI36+(BI36-(BI36*1.15)) -> 155.77007
B37: 31 | E37: 3040 | H37: 2.8 | I37: =ROUNDUP(((BJ37*$N$3)+BJ37),1) -> 207.7 | K37: 0 | AA37: 116.5 | AB37: 125.9 | AC37: =AB37*1.1 -> 138.49 | AE37: =AC37*1.1 -> 152.339 | AH37: =AE37*1.15 -> 175.18985 | AI37: =AH37*1.08 -> 189.20504 | AJ37: =AI37*1.15 -> 217.58579 | AN37: =AJ37*1.05 -> 228.46508 | AO37: 228.5 | AP37: =AO37*1.06 -> 242.21 | AS37: 207.6 | AT37: =AS37 -> 207.6 | AV37: =AT37*1.07 -> 222.132 | BI37: =AV37*1.1 -> 244.3452 | BJ37: =BI37+(BI37-(BI37*1.15)) -> 207.69342
B38: 32 | E38: 3039 | H38: 3 | I38: =ROUNDUP(((BJ38*$N$3)+BJ38),1) -> 207.7 | K38: 0 | AT38: 207.6 | AV38: =AT38*1.07 -> 222.132 | BI38: =AV38*1.1 -> 244.3452 | BJ38: =BI38+(BI38-(BI38*1.15)) -> 207.69342
B39: 33 | E39: 3043 | H39: 2.5 | I39: =ROUNDUP(((BJ39*$N$3)+BJ39),1) -> 188.1 | K39: 0 | AC39: 138.49 | AE39: =AC39*1.06 -> 146.7994 | AH39: =AE39*1.05 -> 154.13937 | AI39: =AH39*1.08 -> 166.47052 | AJ39: 174.66 | AN39: =AJ39*1.015 -> 177.2799 | AO39: 177.3 | AP39: =AO39*1.06 -> 187.938 | AS39: =AP39 -> 187.938 | AT39: =AS39 -> 187.938 | AV39: =AT39*1.07 -> 201.09366 | BI39: =AV39*1.1 -> 221.20303 | BJ39: =BI39+(BI39-(BI39*1.15)) -> 188.02257
B40: 34 | E40: 3041 | H40: 2.5 | I40: =ROUNDUP(((BJ40*$N$3)+BJ40),1) -> 162.3 | K40: 0 | AA40: 116.5 | AB40: 125.9 | AC40: =AB40*1.1 -> 138.49 | AE40: =AC40*1.06 -> 146.7994 | AH40: =AE40*1.05 -> 154.13937 | AI40: =AH40 -> 154.13937 | AJ40: 174.66 | AN40: =AJ40*1.015 -> 177.2799 | AO40: 177.3 | AP40: =AO40*1.06 -> 187.938 | AS40: 162.2 | AT40: =AS40 -> 162.2 | AV40: =AT40*1.07 -> 173.554 | BI40: =AV40*1.1 -> 190.9094 | BJ40: =BI40+(BI40-(BI40*1.15)) -> 162.27299
B41: 35 | E41: 0090, 0096, 7500, 7501, 7504 e 7508 | H41: 2.8 | I41: =ROUNDUP(((BJ41*$N$3)+BJ41),1) -> 175.9 | K41: 0 | AA41: 116.5 | AB41: 125.9 | AC41: =AB41*1.1 -> 138.49 | AE41: =AC41*1.06 -> 146.7994 | AH41: =AE41*1.05 -> 154.13937 | AI41: =AH41*1.08 -> 166.47052 | AJ41: =AI41*1.05 -> 174.79405 | AN41: =AJ41*1.05 -> 183.53375 | AO41: 183.6 | AP41: =AO41*1.1 -> 201.96 | AS41: 202 | AT41: =AS41-((AS41*13)/100) -> 175.74 | AV41: =AT41*1.07 -> 188.0418 | BI41: =AV41*1.1 -> 206.84598 | BJ41: =BI41+(BI41-(BI41*1.15)) -> 175.81908
B42: 36 | C42: OXFORD BLACKOUT | E42: 0410, 0411 e 0414 | H42: 3 | I42: =ROUNDUP(((BJ42*$N$3)+BJ42),1) -> 166.2 | K42: 0 | AA42: 144.7 | AB42: 156.3 | AC42: =AB42*1.1 -> 171.93 | AE42: =AC42*1.06 -> 182.2458 | AH42: =AE42 -> 182.2458 | AI42: =AH42*1.05 -> 191.35809 | AJ42: =AI42 -> 191.35809 | AN42: =AJ42 -> 191.35809 | AO42: 191.4 | AP42: =AO42*1.06 -> 202.884 | AS42: 184.5 | AT42: =AS42-((AS42*10)/100) -> 166.05 | AV42: =AT42*1.07 -> 177.6735 | BI42: =AV42*1.1 -> 195.44085 | BJ42: =BI42+(BI42-(BI42*1.15)) -> 166.12472
...

Sheet Premium
K2: Página 9 - | L2: =Rolô!L2 -> 2026 - v.03 | N2: * DIGITE A PORCENTAGEM PARA MARKUP
B3: CORTINAS LINHA PREMIUM | N3: 0
B4: PRODUTO EM CONFORMIDADE COM A NORMA ABNT NBR 16234: 2014
B6: ITEM | C6: COLEÇÃO | E6: COR | H6: LAR. MAX. | I6: VALOR À VISTA (R$)/M² | K6: IPI | AA6: 42491 | AC6: 42583 | AD6: 43026 | AE6: 43258 | AG6: 43862 | AH6: 43952 | AI6: 44105 | AJ6: 44256 | AK6: 44378 | AL6: 44501 | AO6: 44682 | AQ6: 45658 | AS6: 46082
B7: 1 | C7: ILLUMINÊ | E7: 0630 ao 0633 | H7: 2.8 | I7: =ROUNDUP(((AS7*$N$3)+AS7),1) -> 404.3 | K7: 0 | AA7: 222.6 | AD7: 240.5 | AE7: 264.6 | AG7: =AE7*1.06 -> 280.476 | AH7: =AG7*1.1 -> 308.5236 | AI7: =AH7 -> 308.5236 | AJ7: =AI7*1.05 -> 323.94978 | AK7: =AJ7 -> 323.94978 | AL7: 324 | AM7: =AL7*1.06 -> 343.44 | AO7: =AM7 -> 343.44 | AP7: =AO7*1.07 -> 367.4808 | AQ7: =AP7*1.1 -> 404.22888 | AS7: =AQ7 -> 404.22888
B8: 2 | C8: MELÍADE | E8: 0571, 0581 e 0582 | H8: 2.8 | I8: =ROUNDUP(((AS8*$N$3)+AS8),1) -> 661.9 | K8: 0 | AA8: 364.7 | AD8: 393.9 | AE8: 433.3 | AG8: =AE8*1.06 -> 459.298 | AH8: =AG8*1.1 -> 505.2278 | AI8: =AH8 -> 505.2278 | AJ8: =AI8*1.05 -> 530.48919 | AK8: =AJ8 -> 530.48919 | AL8: 530.5 | AM8: =AL8*1.06 -> 562.33 | AO8: =AM8 -> 562.33 | AP8: =AO8*1.07 -> 601.6931 | AQ8: =AP8*1.1 -> 661.86241 | AS8: =AQ8 -> 661.86241
B9: 3 | E9: 0580 | H9: 3 | K9: 0 | AK9: =AJ9*1.05 -> 0 | AO9: =AM9 -> 0 | AP9: =AO9*1.07 -> 0 | AQ9: =AP9*1.1 -> 0 | AS9: =AQ9 -> 0
B10: 4 | C10: LUMIÉRE 50MM LINEA | E10: 0601, 0606, 0607 | H10: 3 | I10: =ROUNDUP(((AS10*$N$3)+AS10),1) -> 302.7 | K10: 0 | AA10: 238.2 | AD10: 257.3 | AE10: 283.1 | AG10: =AE10*1.06 -> 300.086 | AH10: =AG10*1.1 -> 330.0946 | AI10: =AH10 -> 330.0946 | AJ10: =AI10*1.05 -> 346.59933 | AK10: =AJ10 -> 346.59933 | AL10: 346.6 | AM10: =AL10*1.06 -> 367.396 | AO10: =AM10 -> 367.396 | AP10: =AO10*1.07 -> 393.11372 | AQ10: =AP10*1.1 -> 432.42509 | AS10: =AQ10+(AQ10-(AQ10*1.3)) -> 302.69756
B11: 5 | E11: 0602, 0608 e 0609 | H11: 2.8 | K11: 0 | AK11: =AJ11*1.05 -> 0 | AO11: =AM11 -> 0 | AP11: =AO11*1.07 -> 0 | AQ11: =AP11*1.1 -> 0 | AS11: =AQ11+(AQ11-(AQ11*1.3)) -> 0
B12: 6 | C12: LUMIÉRE 60MM BRISE | E12: 0612 e 0613 | H12: 3 | I12: =ROUNDUP(((AS12*$N$3)+AS12),1) -> 302.7 | K12: 0 | AO12: 367.4 | AP12: =AO12*1.07 -> 393.118 | AQ12: =AP12*1.1 -> 432.4298 | AS12: =302.69 -> 302.69
B13: 7 | C13: LUMIÉRE 55MM BK | E13: 0750, 0751 e 0752 | H13: 3 | I13: =ROUNDUP(((AS13*$N$3)+AS13),1) -> 404.3 | K13: 0 | AO13: 429.3 | AP13: =AO13*1.07 -> 459.351 | AQ13: =AP13*1.1 -> 505.2861 | AS13: =AQ13+(AQ13-(AQ13*1.2)) -> 404.22888
B14: 8 | C14: LUMIÉRE 70MM LUMINA | E14: 0595 ao 0600 | H14: 2.8 | I14: =ROUNDUP(((AS14*$N$3)+AS14),1) -> 338 | K14: 0 | AA14: 248.2 | AD14: 268.1 | AE14: 295 | AG14: =AE14*1.06 -> 312.7 | AH14: =AG14*1.1 -> 343.97 | AI14: =AH14 -> 343.97 | AJ14: =AI14*1.05 -> 361.1685 | AK14: =AJ14 -> 361.1685 | AL14: 361.2 | AM14: =AL14*1.06 -> 382.872 | AO14: =AM14 -> 382.872 | AP14: =AO14*1.07 -> 409.67304 | AQ14: =AP14*1.1 -> 450.64034 | AS14: =AQ14+(AQ14-(AQ14*1.25)) -> 337.98026
B15: 9 | C15: LUMIÉRE 50MM DIAMANTE | E15: 0592, 0593 e 0594 e 0591 (LANÇAMENTO) | H15: 2.8 | I15: =ROUNDUP(((AS15*$N$3)+AS15),1) -> 338 | K15: 0 | AA15: 248.2 | AD15: 268.1 | AE15: 295 | AG15: =AE15*1.06 -> 312.7 | AH15: =AG15*1.1 -> 343.97 | AI15: =AH15 -> 343.97 | AJ15: =AI15*1.05 -> 361.1685 | AK15: =AJ15 -> 361.1685 | AL15: 361.2 | AM15: =AL15*1.06 -> 382.872 | AO15: =AM15 -> 382.872 | AP15: =AO15*1.07 -> 409.67304 | AQ15: =AP15*1.1 -> 450.64034 | AS15: =AQ15+(AQ15-(AQ15*1.25)) -> 337.98026
B16: 10 | C16: LUMIÉRE 50MM ARMONNE | E16: 0823, 0824, 0825, 0826 E 0827 (LANÇAMENTOS) | H16: 2.8 | I16: =ROUNDUP(((AS16*$N$3)+AS16),1) -> 353.8 | K16: 0 | AQ16: 505.3 | AS16: =AQ16+(AQ16-(AQ16*1.3)) -> 353.71
B17: 11 | C17: LUMIÉRE 70MM MALORIE | E17: 0550, 0551, 0552 e 0553 (LANÇAMENTOS) | H17: 3 | I17: =ROUNDUP(((AS17*$N$3)+AS17),1) -> 324.4 | K17: 0 | AQ17: 463.4 | AS17: =AQ17+(AQ17-(AQ17*1.3)) -> 324.38
B18: 12 | C18: LUMIÉRE 70MM ENVELINE | E18: 0730, 0731, 0732, 0733, 0734 e 0735 (LANÇAMENTOS) | H18: 3 | I18: =ROUNDUP(((AS18*$N$3)+AS18),1) -> 315.5 | K18: 0 | AQ18: 450.7 | AS18: =AQ18+(AQ18-(AQ18*1.3)) -> 315.49
B19: 13 | C19: LUMIÉRE 50MM VIVANCE | E19: 0820, 0821 e 0822 (LANÇAMENTOS) | H19: 2.8 | I19: =ROUNDUP(((AS19*$N$3)+AS19),1) -> 353.8 | K19: 0 | AQ19: 505.3 | AS19: =AQ19+(AQ19-(AQ19*1.3)) -> 353.71
B20: 14 | C20: INFINITY | E20: 0620 ao 0622 | H20: 2.5 | I20: =ROUNDUP(((AS20*$N$3)+AS20),1) -> 411.9 | K20: 0 | AA20: 238.2 | AD20: 257.3 | AE20: 283.1 | AG20: =AE20*1.06 -> 300.086 | AH20: =AG20*1.1 -> 330.0946 | AI20: =AH20 -> 330.0946 | AJ20: =AI20 -> 330.0946 | AK20: =AJ20 -> 330.0946 | AL20: 330.1 | AM20: =AL20*1.06 -> 349.906 | AO20: =AM20 -> 349.906 | AP20: =AO20*1.07 -> 374.39942 | AQ20: =AP20*1.1 -> 411.83936 | AS20: =AQ20 -> 411.83936
B21: 15 | C21: ETERNITY | E21: 0611 | H21: 2.5 | I21: =ROUNDUP(((AS21*$N$3)+AS21),1) -> 411.9 | K21: 0 | AA21: 238.2 | AD21: 257.3 | AE21: 283.1 | AG21: =AE21*1.06 -> 300.086 | AH21: =AG21*1.1 -> 330.0946 | AI21: =AH21 -> 330.0946 | AJ21: =AI21 -> 330.0946 | AK21: =AJ21 -> 330.0946 | AL21: 330.1 | AM21: =AL21*1.06 -> 349.906 | AO21: =AM21 -> 349.906 | AP21: =AO21*1.07 -> 374.39942 | AQ21: =AP21*1.1 -> 411.83936 | AS21: =AQ21 -> 411.83936
B22: 16 | C22: ETERNITY LINE | E22: 0615 e 0616 | H22: 2.5 | I22: =ROUNDUP(((AS22*$N$3)+AS22),1) -> 411.9 | K22: 0 | AA22: 238.2 | AD22: 257.3 | AE22: 283.1 | AG22: =AE22*1.06 -> 300.086 | AH22: =AG22*1.1 -> 330.0946 | AI22: =AH22 -> 330.0946 | AJ22: =AI22 -> 330.0946 | AK22: =AJ22 -> 330.0946 | AL22: 330.1 | AM22: =AL22*1.06 -> 349.906 | AO22: =AM22 -> 349.906 | AP22: =AO22*1.07 -> 374.39942 | AQ22: =AP22*1.1 -> 411.83936 | AS22: =AQ22 -> 411.83936
B23: 17 | C23: GALAXY | E23: 0641 - PROMOÇÃO | H23: 2.5 | I23: =ROUNDUP(((AS23*$N$3)+AS23),1) -> 108.2 | K23: 0 | AA23: 80 | AD23: 86.4 | AE23: 74.3 | AF23: =67.5*1.1 -> 74.25 | AG23: 78.8 | AH23: =AG23*1.1 -> 86.68 | AI23: 86.63 | AJ23: =AI23 -> 86.63 | AK23: =AJ23 -> 86.63 | AL23: 86.7 | AM23: =AL23*1.06 -> 91.902 | AO23: =AM23 -> 91.902 | AP23: =AO23*1.07 -> 98.33514 | AQ23: =AP23*1.1 -> 108.16865 | AS23: =AQ23 -> 108.16865
B24: 18 | C24: PASSIONE | E24: 0670 e 0672 | H24: - | I24: =ROUNDUP(((AS24*$N$3)+AS24),1) -> 409.2 | K24: 0 | AA24: 298 | AD24: 321.9 | AE24: 354.1 | AG24: =AE24*1.06 -> 375.346 | AH24: =AG24*1.04 -> 390.35984 | AI24: =AH24 -> 390.35984 | AJ24: =AI24*1.05 -> 409.87783 | AK24: =AJ24 -> 409.87783 | AL24: 409.9 | AM24: =AL24*1.06 -> 434.494 | AO24: =AM24 -> 434.494 | AP24: =AO24*1.07 -> 464.90858 | AQ24: =AP24*1.1 -> 511.39944 | AS24: =AQ24+(AQ24-(AQ24*1.2)) -> 409.11955
B25: 19 | E25: 0671 | H25: - | I25: =ROUNDUP(((AS25*$N$3)+AS25),1) -> 286.5 | K25: 0 | AA25: 208.6 | AD25: 225.3 | AE25: 247.9 | AG25: =AE25*1.06 -> 262.774 | AH25: =AG25*1.04 -> 273.28496 | AI25: =AH25 -> 273.28496 | AJ25: =AI25*1.05 -> 286.94921 | AK25: =AJ25 -> 286.94921 | AL25: 287 | AM25: =AL25*1.06 -> 304.22 | AO25: =AM25 -> 304.22 | AP25: =AO25*1.07 -> 325.5154 | AQ25: =AP25*1.1 -> 358.06694 | AS25: =AQ25+(AQ25-(AQ25*1.2)) -> 286.45355
B26: 20 | C26: L'AMOUR | E26: 0980, 0981, 0982,0983 e 0984 | H26: 7.2 | I26: =ROUNDUP(((AS26*$N$3)+AS26),1) -> 253.3 | K26: 0 | AP26: 255.8 | AQ26: =AP26*1.1 -> 281.38 | AS26: =AQ26+(AQ26-(AQ26*1.1)) -> 253.242
B27: 21 | C27: ROLÔ STILLO | AO27: =AM27 -> 0 | AP27: =AO27*1.07 -> 0 | AQ27: =AP27*1.1 -> 0 | AS27: 46082
B28: 22 | C28: STILLO BASIC | E28: 0110, 0111 e 0129 | H28: 2.7 | I28: =ROUNDUP(((AS28*$N$3)+AS28),1) -> 169.7 | K28: 0 | AA28: 160.2 | AC28: 129.78 | AD28: 135 | AE28: 148.5 | AG28: =AE28*1.06 -> 157.41 | AH28: =AG28*1.07 -> 168.4287 | AI28: =AH28*1.08 -> 181.903 | AJ28: =AI28*1.05 -> 190.99815 | AK28: =AJ28 -> 190.99815 | AL28: 191 | AM28: =AL28*1.06 -> 202.46 | AO28: 182.3 | AP28: =AO28*1.07 -> 195.061 | AQ28: =AP28*1.1 -> 214.5671 | AR28: =(AQ28*(-7%))+AQ28 -> 199.5474 | AS28: =AR28+(AR28-(AR28*1.15)) -> 169.61529
B29: 23 | E29: 0127 | H29: 3 | I29: =ROUNDUP(((AS29*$N$3)+AS29),1) -> 169.7 | K29: 0 | AQ29: 214.6 | AR29: =(AQ29*(-7%))+AQ29 -> 199.578 | AS29: =AR29+(AR29-(AR29*1.15)) -> 169.6413
B30: 24 | E30: 0113, 0116 e 0119 | H30: 2.15 | I30: =ROUNDUP(((AS30*$N$3)+AS30),1) -> 214.6 | K30: 0 | AE30: 148.5 | AG30: =AE30*1.06 -> 157.41 | AH30: =AG30*1.07 -> 168.4287 | AI30: =AH30*1.08 -> 181.903 | AJ30: =AI30*1.05 -> 190.99815 | AK30: =AJ30 -> 190.99815 | AL30: 191 | AM30: =AL30*1.06 -> 202.46 | AO30: 182.3 | AP30: =AO30*1.07 -> 195.061 | AQ30: =AP30*1.1 -> 214.5671 | AR30: =AQ30 -> 214.5671 | AS30: 214.6
B31: 25 | E31: 0115 | H31: 2.15 | I31: =ROUNDUP(((AS31*$N$3)+AS31),1) -> 169.7 | AQ31: 214.56 | AR31: =(AQ31*(-7%))+AQ31 -> 199.5408 | AS31: =AR31+(AR31-(AR31*1.15)) -> 169.60968
B32: 26 | C32: STILLO COLOR SEMI-BK | E32: 0202 ao 0207, 0217, 0218 e 0219 | H32: 2.8 | I32: =ROUNDUP(((AS32*$N$3)+AS32),1) -> 188.4 | K32: 0 | AJ32: 268.4 | AK32: =AJ32 -> 268.4 | AL32: 268.4 | AM32: =AL32*1.06 -> 284.504 | AO32: =AM32 -> 284.504 | AP32: =AO32*1.07 -> 304.41928 | AQ32: =AP32*1.1 -> 334.86121 | AR32: =(AQ32*(-25%))+AQ32 -> 251.14591 | AS32: =AR32+(AR32-(AR32*1.25)) -> 188.35943
B33: 27 | E33: 0213 | H33: 2.7 | I33: =ROUNDUP(((AS33*$N$3)+AS33),1) -> 317.3 | K33: 0 | AO33: 322 | AP33: =AO33*1.07 -> 344.54 | AQ33: =AP33*1.1 -> 378.994 | AR33: =(AQ33*(-7%))+AQ33 -> 352.46442 | AS33: =AR33+(AR33-(AR33*1.1)) -> 317.21798
B34: 28 | C34: STILLO SCREEN | E34: 0320, 0321 e 0323 | H34: 2.4 | I34: =ROUNDUP(((AS34*$N$3)+AS34),1) -> 266.4 | K34: 0 | AA34: 165.5 | AD34: 172.2 | AE34: 189.5 | AG34: =AE34*1.06 -> 200.87 | AH34: =AG34*1.1 -> 220.957 | AI34: =AH34*1.08 -> 238.63356 | AJ34: =AI34*1.1 -> 262.49692 | AK34: =AJ34*1.05 -> 275.62176 | AL34: 275.7 | AM34: =AL34*1.06 -> 292.242 | AO34: =AM34 -> 292.242 | AP34: =AO34*1.07 -> 312.69894 | AQ34: =AP34*1.1 -> 343.96883 | AR34: =(AQ34*(-12%))+AQ34 -> 302.69257 | AS34: =AR34+(AR34-(AR34*1.12)) -> 266.36947
B35: 29 | C35: STILLO ACCORDIAN | E35: 0201 | H35: 2.6 | I35: =ROUNDUP(((AS35*$N$3)+AS35),1) -> 202.1 | K35: 0 | AA35: 129.8 | AD35: 135 | AE35: 148.5 | AG35: =AE35*1.06 -> 157.41 | AH35: =AG35*1.1 -> 173.151 | AI35: =AH35 -> 173.151 | AJ35: =AI35*1.1 -> 190.4661 | AK35: =AJ35 -> 190.4661 | AL35: 190.5 | AM35: =AL35*1.06 -> 201.93 | AO35: 171.7 | AP35: =AO35*1.07 -> 183.719 | AQ35: =AP35*1.1 -> 202.0909 | AR35: =AQ35 -> 202.0909 | AS35: 202.1
B36: 30 | AO36: =AM36 -> 0 | AP36: =AO36*1.07 -> 0 | AQ36: =AP36*1.1 -> 0 | AR36: =(AQ36*(-7%))+AQ36 -> 0 | AS36: =AR36+(AR36-(AR36*1.15)) -> 0
B37: 31 | C37: STILLO VERNACCIA | E37: 0270, 0271, 0275 e 0277 | H37: 2.7 | I37: =ROUNDUP(((AS37*$N$3)+AS37),1) -> 214.6 | K37: 0 | AA37: 148.2 | AD37: 154.2 | AE37: 169.7 | AG37: =AE37*1.06 -> 179.882 | AH37: =AG37*1.07 -> 192.47374 | AI37: =AH37 -> 192.47374 | AJ37: =AI37*1.05 -> 202.09743 | AK37: =AJ37 -> 202.09743 | AL37: 202.1 | AM37: =AL37*1.06 -> 214.226 | AO37: 182.3 | AP37: =AO37*1.07 -> 195.061 | AQ37: =AP37*1.1 -> 214.5671 | AR37: =AQ37 -> 214.5671 | AS37: 214.6
B38: 32 | E38: 0274 - PROMOÇÃO | H38: 2.5 | I38: =ROUNDUP(((AS38*$N$3)+AS38),1) -> 108.2 | K38: 0 | AA38: 148.2 | AD38: 154.2 | AE38: 74.3 | AF38: =67.5*1.1 -> 74.25 | AG38: =AE38*1.06 -> 78.758 | AH38: =AG38*1.1 -> 86.6338 | AI38: =AH38 -> 86.6338 | AJ38: =AI38 -> 86.6338 | AK38: =AJ38 -> 86.6338 | AL38: 86.7 | AM38: =AL38*1.06 -> 91.902 | AO38: =AM38 -> 91.902 | AP38: =AO38*1.07 -> 98.33514 | AQ38: =AP38*1.1 -> 108.16865 | AR38: =AQ38 -> 108.16865 | AS38: 108.2
B39: 33 | C39: AVALON | E39: 0526, 0527, 0528, 0529 e 0530 | H39: 2.7 | I39: =ROUNDUP(((AS39*$N$3)+AS39),1) -> 120.3 | K39: 0 | AH39: 120 | AI39: =AH39 -> 120 | AJ39: =AI39*1.05 -> 126 | AK39: =AJ39 -> 126 | AL39: 126 | AM39: =AL39*1.06 -> 133.56 | AO39: =AM39 -> 133.56 | AP39: =AO39*1.07 -> 142.9092 | AQ39: =AP39*1.1 -> 157.20012 | AR39: =(AQ39*(-10%))+AQ39 -> 141.48011 | AS39: =AR39+(AR39-(AR39*1.15)) -> 120.25809
B40: 34 | E40: 0518 | H40: 2.7 | I40: =ROUNDUP(((AS40*$N$3)+AS40),1) -> 151 | K40: 0 | AO40: 167.6 | AP40: =AO40*1.07 -> 179.332 | AQ40: =AP40*1.1 -> 197.2652 | AR40: =(AQ40*(-10%))+AQ40 -> 177.53868 | AS40: =AR40+(AR40-(AR40*1.15)) -> 150.90788
B41: 35 | C41: SANTORINI | E41: 0534 ao 0536 | H41: 2.7 | I41: =ROUNDUP(((AS41*$N$3)+AS41),1) -> 170.7 | K41: 0 | AD41: 141.1 | AE41: 155.3 | AG41: =AE41*1.06 -> 164.618 | AH41: =AG41*1.07 -> 176.14126 | AI41: =AH41 -> 176.14126 | AJ41: =AI41*1.05 -> 184.94832 | AK41: =AJ41 -> 184.94832 | AL41: 185 | AM41: =AL41*1.06 -> 196.1 | AO41: =AM41 -> 196.1 | AP41: =AO41*1.07 -> 209.827 | AQ41: =AP41*1.1 -> 230.8097 | AR41: =(AQ41*(-13%))+AQ41 -> 200.80444 | AS41: =AR41+(AR41-(AR41*1.15)) -> 170.68377
B42: 36 | C42: LEVANZO | E42: 0545 ao 0549 | H42: 2.7 | I42: =ROUNDUP(((AS42*$N$3)+AS42),1) -> 196.7 | K42: 0 | AD42: 148.5 | AE42: 163.4 | AG42: =AE42*1.06 -> 173.204 | AH42: =AG42*1.07 -> 185.32828 | AI42: =AH42 -> 185.32828 | AJ42: =AI42*1.05 -> 194.59469 | AK42: =AJ42 -> 194.59469 | AL42: 194.6 | AM42: =AL42*1.06 -> 206.276 | AO42: =AM42 -> 206.276 | AP42: =AO42*1.07 -> 220.71532 | AQ42: =AP42*1.1 -> 242.78685 | AR42: =(AQ42*(-10%))+AQ42 -> 218.50817 | AS42: =AR42+(AR42-(AR42*1.1)) -> 196.65735
...

Sheet Romana
K2: Página 12 - | L2: =Rolô!L2 -> 2026 - v.03 | N2: * DIGITE A PORCENTAGEM PARA MARKUP
B3: CORTINA ROMANA | N3: 0
B4: PRODUTO EM CONFORMIDADE COM A NORMA ABNT NBR 16234: 2014
B6: ITEM | C6: COLEÇÃO | E6: COR | H6: LAR. MAX. | I6: VALOR À VISTA (R$)/M² | K6: IPI | AA6: 42491 | AB6: 43026 | AC6: 43258 | AE6: 43862 | AF6: 43891 | AG6: 43952 | AH6: 44105 | AI6: 44256 | AJ6: 44287 | AK6: 44501 | AN6: 44682 | AP6: desc/acres | AU6: 45658
B7: 1 | C7: SCREEN 1% | E7: 0001, 0005 e 0006, 1010, 1030 e 1031 | H7: 3 | I7: =ROUNDUP(((AV7*$N$3)+AV7),1) -> 211 | K7: 0 | AA7: 146.1 | AB7: 157.8 | AC7: 173.6 | AE7: =AC7*1.06 -> 184.016 | AG7: =AE7*1.1 -> 202.4176 | AH7: =AG7 -> 202.4176 | AI7: =AH7 -> 202.4176 | AJ7: =AI7 -> 202.4176 | AK7: 202.5 | AL7: =AK7*1.06 -> 214.65 | AN7: =Rolô!I7*1.14 -> 189.924 | AO7: 210.9 | AP7: =AN7-AL7 -> -24.726 | AQ7: =AO7*1.07 -> 225.663 | AU7: =AQ7*1.1 -> 248.2293 | AV7: =AU7+(AU7-(AU7*1.15)) -> 210.99491
B8: 2 | C8: SCREEN FIBER GLASS 1% | E8: 6001 | H8: 3 | I8: =ROUNDUP(((AV8*$N$3)+AV8),1) -> 304.8 | K8: 0 | AA8: 175 | AB8: 189 | AC8: 207.9 | AE8: =AC8*1.06 -> 220.374 | AG8: =AE8*1.15 -> 253.4301 | AH8: =AG8*1.08 -> 273.70451 | AI8: =AH8*1.05 -> 287.38973 | AJ8: =AI8 -> 287.38973 | AK8: 287.4 | AL8: =AK8*1.06 -> 304.644 | AN8: =AL8 -> 304.644 | AO8: 304.644 | AP8: =AN8-AL8 -> 0 | AQ8: =AO8*1.07 -> 325.96908 | AU8: =AQ8*1.1 -> 358.56599 | AV8: =AU8+(AU8-(AU8*1.15)) -> 304.78109
B9: 3 | C9: SCREEN 3% | E9: 3001, 3002, 3008, 3017, 3060 e 3061 | H9: 3 | I9: =ROUNDUP(((AV9*$N$3)+AV9),1) -> 190.9 | K9: 0 | AA9: 128.4 | AB9: 138.7 | AC9: 152.6 | AE9: =AC9*1.06 -> 161.756 | AG9: =AE9*1.08 -> 174.69648 | AH9: =AG9 -> 174.69648 | AI9: =AH9 -> 174.69648 | AJ9: =AI9*1.03 -> 179.93737 | AK9: 180 | AL9: =AK9*1.06 -> 190.8 | AN9: =AL9 -> 190.8 | AO9: 190.8 | AP9: =AN9-AL9 -> 0 | AQ9: =AO9*1.07 -> 204.156 | AU9: =AQ9*1.1 -> 224.5716 | AV9: =AU9+(AU9-(AU9*1.15)) -> 190.88586
B10: 4 | E10: 3009 ao 3011, 3018 e 3019 | H10: 3 | I10: =ROUNDUP(((AV10*$N$3)+AV10),1) -> 204.4 | K10: 0 | AA10: 128.4 | AB10: 138.7 | AC10: 152.6 | AE10: =AC10*1.06 -> 161.756 | AG10: =AE10*1.08 -> 174.69648 | AH10: =AG10 -> 174.69648 | AI10: =AH10*1.05 -> 183.4313 | AJ10: =AI10*1.05 -> 192.60287 | AK10: 192.7 | AL10: =AK10*1.06 -> 204.262 | AN10: =AL10 -> 204.262 | AO10: 204.262 | AP10: =AN10-AL10 -> 0 | AQ10: =AO10*1.07 -> 218.56034 | AU10: =AQ10*1.1 -> 240.41637 | AV10: =AU10+(AU10-(AU10*1.15)) -> 204.35392
B11: 5 | E11: 3012 e 3013 | H11: 3 | I11: =ROUNDUP(((AV11*$N$3)+AV11),1) -> 194.6 | K11: 0 | AI11: 183.43 | AJ11: =AI11 -> 183.43 | AK11: 183.5 | AL11: =AK11*1.06 -> 194.51 | AN11: =AL11 -> 194.51 | AO11: 194.51 | AP11: =AN11-AL11 -> 0 | AQ11: =AO11*1.07 -> 208.1257 | AU11: =AQ11*1.1 -> 228.93827 | AV11: =AU11+(AU11-(AU11*1.15)) -> 194.59753
B12: 6 | E12: 3014, 3015 | H12: 3 | I12: =ROUNDUP(((AV12*$N$3)+AV12),1) -> 213.4 | K12: 0 | AE12: =AE10 -> 161.756 | AG12: =AE12*1.15 -> 186.0194 | AH12: =AG12 -> 186.0194 | AI12: =AH12*1.05 -> 195.32037 | AJ12: =AI12*1.03 -> 201.17998 | AK12: 201.2 | AL12: =AK12*1.06 -> 213.272 | AN12: =AL12 -> 213.272 | AO12: 213.272 | AP12: =AN12-AL12 -> 0 | AQ12: =AO12*1.07 -> 228.20104 | AU12: =AQ12*1.1 -> 251.02114 | AV12: =AU12+(AU12-(AU12*1.15)) -> 213.36797
B13: 7 | C13: SCREEN FIBER GLASS 3% | E13: 6101 | H13: 3 | I13: =ROUNDUP(((AV13*$N$3)+AV13),1) -> 268.6 | K13: 0 | AA13: 154 | AB13: 166.4 | AC13: 183.1 | AE13: =AC13*1.06 -> 194.086 | AG13: =AE13*1.15 -> 223.1989 | AH13: =AG13*1.08 -> 241.05481 | AI13: =AH13*1.05 -> 253.10755 | AJ13: =AI13 -> 253.10755 | AK13: 253.2 | AL13: =AK13*1.06 -> 268.392 | AN13: =AL13 -> 268.392 | AO13: 268.392 | AP13: =AN13-AL13 -> 0 | AQ13: =AO13*1.07 -> 287.17944 | AU13: =AQ13*1.1 -> 315.89738 | AV13: =AU13+(AU13-(AU13*1.15)) -> 268.51278
B14: 8 | C14: SCREEN 5% | E14: 3070 ao 3076, 3078 e 3079 | H14: 3 | I14: =ROUNDUP(((AV14*$N$3)+AV14),1) -> 178.2 | K14: 0 | AA14: 119.8 | AB14: 129.4 | AC14: 142.4 | AE14: =AC14*1.06 -> 150.944 | AG14: =AE14*1.08 -> 163.01952 | AH14: =AG14 -> 163.01952 | AI14: =AH14 -> 163.01952 | AJ14: =AI14*1.03 -> 167.91011 | AK14: 168 | AL14: =AK14*1.06 -> 178.08 | AN14: =AL14 -> 178.08 | AO14: 178.08 | AP14: =AN14-AL14 -> 0 | AQ14: =AO14*1.07 -> 190.5456 | AU14: =AQ14*1.1 -> 209.60016 | AV14: =AU14+(AU14-(AU14*1.15)) -> 178.16014
B15: 9 | E15: 3096, 3097 e 3098 | H15: 2.5 | AQ15: =AO15*1.07 -> 0 | AU15: =AQ15*1.1 -> 0 | AV15: =AU15+(AU15-(AU15*1.15)) -> 0
B16: 10 | C16: SCREEN FIBER GLASS 5% | E16: 6202 | H16: 3 | I16: =ROUNDUP(((AV16*$N$3)+AV16),1) -> 250.7 | K16: 0 | AA16: 143.8 | AB16: 155.4 | AC16: 171 | AE16: =AC16*1.06 -> 181.26 | AG16: =AE16*1.15 -> 208.449 | AH16: =AG16*1.08 -> 225.12492 | AI16: =AH16*1.05 -> 236.38117 | AJ16: =AI16 -> 236.38117 | AK16: 236.4 | AL16: =AK16*1.06 -> 250.584 | AN16: =AL16 -> 250.584 | AO16: 250.584 | AP16: =AN16-AL16 -> 0 | AQ16: =AO16*1.07 -> 268.12488 | AU16: =AQ16*1.1 -> 294.93737 | AV16: =AU16+(AU16-(AU16*1.15)) -> 250.69676
B17: 11 | C17: SCREEN CRISTAL 5% | E17: 3100 | H17: 3 | I17: =ROUNDUP(((AV17*$N$3)+AV17),1) -> 229.6 | K17: 0 | AA17: 146.1 | AB17: 157.8 | AC17: 173.6 | AE17: =AC17*1.06 -> 184.016 | AG17: =AE17*1.12 -> 206.09792 | AH17: =AG17 -> 206.09792 | AI17: =AH17*1.05 -> 216.40282 | AJ17: =AI17 -> 216.40282 | AK17: 216.5 | AL17: =AK17*1.06 -> 229.49 | AN17: =AL17 -> 229.49 | AO17: 229.49 | AP17: =AN17-AL17 -> 0 | AQ17: =AO17*1.07 -> 245.5543 | AU17: =AQ17*1.1 -> 270.10973 | AV17: =AU17+(AU17-(AU17*1.15)) -> 229.59327
B18: 12 | C18: SCREEN RÚSTICO 3% | E18: 3150 e 3151 | H18: 3 | I18: =ROUNDUP(((AV18*$N$3)+AV18),1) -> 205.3 | K18: 0 | AA18: 127.1 | AB18: 137.3 | AC18: 151.1 | AE18: =AC18*1.06 -> 160.166 | AG18: =AE18*1.15 -> 184.1909 | AH18: =AG18 -> 184.1909 | AI18: =AH18*1.05 -> 193.40044 | AJ18: =AI18 -> 193.40044 | AK18: 193.5 | AL18: =AK18*1.06 -> 205.11 | AN18: =AL18 -> 205.11 | AO18: 205.11 | AP18: =AN18-AL18 -> 0 | AQ18: =AO18*1.07 -> 219.4677 | AU18: =AQ18*1.1 -> 241.41447 | AV18: =AU18+(AU18-(AU18*1.15)) -> 205.2023
B19: 13 | C19: SCREEN RÚSTICO 5% | E19: 3159, 3160, 3161, 3162 e 3163 | H19: 2.5 | I19: =ROUNDUP(((AV19*$N$3)+AV19),1) -> 202.4 | K19: 0 | AE19: =#REF! -> #REF! | AG19: =AE19*1.08 -> #REF! | AH19: =AG19*1.05 -> #REF! | AI19: =AH19*1.05 -> #REF! | AJ19: =AI19 -> #REF! | AK19: 190.8 | AL19: =AK19*1.06 -> 202.248 | AN19: =AL19 -> 202.248 | AO19: 202.248 | AP19: =AN19-AL19 -> 0 | AQ19: =AO19*1.07 -> 216.40536 | AU19: =AQ19*1.1 -> 238.0459 | AV19: =AU19+(AU19-(AU19*1.15)) -> 202.33901
B20: 14 | E20: 3155 e 3156 | H20: 3 | I20: =ROUNDUP(((AV20*$N$3)+AV20),1) -> 225.7 | K20: 0 | AA20: 127.1 | AB20: 137.3 | AC20: 151.1 | AE20: =AC20*1.06 -> 160.166 | AG20: =AE20*1.15 -> 184.1909 | AH20: =AG20*1.05 -> 193.40044 | AI20: =AH20*1.1 -> 212.74049 | AJ20: =AI20 -> 212.74049 | AK20: 212.8 | AL20: =AK20*1.06 -> 225.568 | AN20: =AL20 -> 225.568 | AO20: 225.568 | AP20: =AN20-AL20 -> 0 | AQ20: =AO20*1.07 -> 241.35776 | AU20: =AQ20*1.1 -> 265.49354 | AV20: =AU20+(AU20-(AU20*1.15)) -> 225.66951
B21: 15 | C21: SCREEN REFLEX | E21: 3121, 3122 e 3123 | H21: 3 | I21: =ROUNDUP(((AV21*$N$3)+AV21),1) -> 275 | K21: 0 | AA21: 167 | AB21: 180.4 | AC21: 198.5 | AE21: =AC21*1.06 -> 210.41 | AG21: =AE21*1.12 -> 235.6592 | AH21: =AG21 -> 235.6592 | AI21: =AH21*1.1 -> 259.22512 | AJ21: =AI21 -> 259.22512 | AK21: 259.3 | AL21: =AK21*1.06 -> 274.858 | AN21: =AL21 -> 274.858 | AO21: 274.858 | AP21: =AN21-AL21 -> 0 | AQ21: =AO21*1.07 -> 294.09806 | AU21: =AQ21*1.1 -> 323.50787 | AV21: =AU21+(AU21-(AU21*1.15)) -> 274.98169
B22: 16 | C22: SCREEN BK | E22: 3200, 3201 e 3203 | H22: 2.5 | I22: =ROUNDUP(((AV22*$N$3)+AV22),1) -> 283.1 | K22: 0 | AO22: 282.9 | AQ22: =AO22*1.07 -> 302.703 | AU22: =AQ22*1.1 -> 332.9733 | AV22: =AU22+(AU22-(AU22*1.15)) -> 283.02731
B23: 17 | C23: IBIZA | E23: 3350, 3351 e 3353 | H23: 2.6 | I23: =ROUNDUP(((AV23*$N$3)+AV23),1) -> 202.5 | K23: 0 | AA23: 110.9 | AB23: 119.8 | AC23: 131.8 | AE23: =AC23*1.06 -> 139.708 | AG23: =AE23*1.15 -> 160.6642 | AH23: =AG23*1.08 -> 173.51734 | AI23: =AH23*1.1 -> 190.86907 | AJ23: =AI23 -> 190.86907 | AK23: 190.9 | AL23: =AK23*1.06 -> 202.354 | AN23: =AL23 -> 202.354 | AO23: 202.354 | AP23: =AN23-AL23 -> 0 | AQ23: =AO23*1.07 -> 216.51878 | AU23: =AQ23*1.1 -> 238.17066 | AV23: =AU23+(AU23-(AU23*1.15)) -> 202.44506
B24: 18 | C24: BLACKOUT PINPOINT | E24: 0180 ao 0183 e 0186 ao 0190 - larg. especial 2.5 | H24: 2.5 | I24: =ROUNDUP(((AV24*$N$3)+AV24),1) -> 187.8 | K24: 0.1 | AA24: 127.6 | AB24: 137.9 | AC24: 151.7 | AE24: =AC24*1.06 -> 160.802 | AG24: =AE24*1.12 -> 180.09824 | AH24: =AG24*1.05 -> 189.10315 | AI24: =AH24*1.05 -> 198.55831 | AJ24: =AI24*1.05 -> 208.48623 | AK24: 208.5 | AL24: =AK24*1.06 -> 221.01 | AN24: =Rolô!I24*1.14 -> 169.062 | AO24: 187.644 | AP24: =AN24-AL24 -> -51.948 | AQ24: =AO24*1.07 -> 200.77908 | AU24: =AQ24*1.1 -> 220.85699 | AV24: =AU24+(AU24-(AU24*1.15)) -> 187.72844
B25: 19 | AE25: =AE24 -> 160.802 | AG25: =AE25*1.12 -> 180.09824 | AQ25: =AO25*1.07 -> 0 | AU25: =AQ25*1.1 -> 0 | AV25: =AU25+(AU25-(AU25*1.15)) -> 0
B26: 20 | E26: 0180 ao 0183 e 0186, 0187 e 0190 - larg. especial 3 | H26: 3 | I26: =ROUNDUP(((AV26*$N$3)+AV26),1) -> 193.6 | K26: 0.1 | AE26: =AE25 -> 160.802 | AG26: =AE26*1.15 -> 184.9223 | AH26: =AG26*1.05 -> 194.16841 | AI26: =AH26*1.05 -> 203.87684 | AJ26: =AI26*1.05 -> 214.07068 | AK26: 214.1 | AL26: =AK26*1.06 -> 226.946 | AN26: =Rolô!I26*1.14 -> 174.192 | AO26: 193.458 | AP26: =AN26-AL26 -> -52.754 | AQ26: =AO26*1.07 -> 207.00006 | AU26: =AQ26*1.1 -> 227.70007 | AV26: =AU26+(AU26-(AU26*1.15)) -> 193.54506
B27: 21 | E27: 0180 ao 0183 e 0186, 0187 e 0190 | H27: 2 | I27: =ROUNDUP(((AV27*$N$3)+AV27),1) -> 177.2 | K27: 0.1 | AA27: 114.1 | AB27: 123.3 | AC27: 135.7 | AE27: =AC27*1.06 -> 143.842 | AG27: =AE27*1.12 -> 161.10304 | AH27: =AG27*1.05 -> 169.15819 | AI27: =AH27*1.1 -> 186.07401 | AJ27: =AI27*1.05 -> 195.37771 | AK27: 195.4 | AL27: =AK27*1.06 -> 207.124 | AN27: =Rolô!I27*1.14 -> 159.486 | AO27: 177.042 | AP27: =AN27-AL27 -> -47.638 | AQ27: =AO27*1.07 -> 189.43494 | AU27: =AQ27*1.1 -> 208.37843 | AV27: =AU27+(AU27-(AU27*1.15)) -> 177.12167
B28: 22 | AB28: 123.3 | AC28: 135.7 | AE28: =AC28*1.06 -> 143.842 | AG28: =AE28*1.12 -> 161.10304 | AQ28: =AO28*1.07 -> 0 | AU28: =AQ28*1.1 -> 0 | AV28: =AU28+(AU28-(AU28*1.15)) -> 0
B29: 23 | C29: REQUINTE BK | E29: 0088 | H29: 2 | I29: =ROUNDUP(((AV29*$N$3)+AV29),1) -> 212.8 | K29: 0 | AA29: 115 | AB29: 124.2 | AC29: 136.7 | AE29: =AC29*1.06 -> 144.902 | AG29: =AE29*1.12 -> 162.29024 | AH29: =AG29*1.08 -> 175.27346 | AI29: =AH29*1.05 -> 184.03713 | AJ29: =AI29*1.05 -> 193.23899 | AK29: 193.3 | AL29: =AK29*1.1 -> 212.63 | AN29: =AL29 -> 212.63 | AO29: 212.63 | AP29: =AN29-AL29 -> 0 | AQ29: =AO29*1.07 -> 227.5141 | AU29: =AQ29*1.1 -> 250.26551 | AV29: =AU29+(AU29-(AU29*1.15)) -> 212.72568
B30: 24 | E30: 0101, 0102, 3042, 3044, 7517 ao 7523) | H30: 3 | I30: =ROUNDUP(((AV30*$N$3)+AV30),1) -> 172.5 | K30: 0 | AO30: 172.4 | AP30: 172.4 | AQ30: =AO30*1.07 -> 184.468 | AU30: =AQ30*1.1 -> 202.9148 | AV30: =AU30+(AU30-(AU30*1.15)) -> 172.47758
B31: 25 | E31: 0103 | H31: 2.5 | I31: =ROUNDUP(((AV31*$N$3)+AV31),1) -> 172.5 | K31: 0 | AA31: 115 | AB31: 124.2 | AC31: 136.7 | AE31: =AC31*1.06 -> 144.902 | AG31: =AE31*1.08 -> 156.49416 | AH31: =AG31 -> 156.49416 | AI31: =AH31*1.05 -> 164.31887 | AJ31: =AI31 -> 164.31887 | AK31: 164.4 | AL31: =AK31*1.06 -> 174.264 | AN31: =Rolô!I31*1.14 -> 155.268 | AO31: 172.368 | AP31: =AN31-AL31 -> -18.996 | AQ31: =AO31*1.07 -> 184.43376 | AU31: =AQ31*1.1 -> 202.87714 | AV31: =AU31+(AU31-(AU31*1.15)) -> 172.44557
B32: 26 | E32: 0105, 7511 ao 7516 | H32: 3 | I32: =ROUNDUP(((AV32*$N$3)+AV32),1) -> 174.4 | K32: 0 | AO32: 174.3 | AQ32: =AO32*1.07 -> 186.501 | AU32: =AQ32*1.1 -> 205.1511 | AV32: =AU32+(AU32-(AU32*1.15)) -> 174.37844
B33: 27 | E33: 0106 e 0107 | H33: 2.4 | I33: =ROUNDUP(((AV33*$N$3)+AV33),1) -> 174.4 | K33: 0 | AA33: 115 | AB33: 124.2 | AC33: 136.7 | AE33: =AC33*1.06 -> 144.902 | AG33: =AE33*1.08 -> 156.49416 | AH33: =AG33 -> 156.49416 | AI33: =AH33*1.05 -> 164.31887 | AJ33: =AI33 -> 164.31887 | AK33: 164.4 | AL33: =AK33*1.06 -> 174.264 | AN33: =AL33 -> 174.264 | AO33: 174.264 | AP33: =AN33-AL33 -> 0 | AQ33: =AO33*1.07 -> 186.46248 | AU33: =AQ33*1.1 -> 205.10873 | AV33: =AU33+(AU33-(AU33*1.15)) -> 174.34242
B34: 28 | E34: 3031 | H34: 2.4 | I34: =ROUNDUP(((AV34*$N$3)+AV34),1) -> 221.3 | K34: 0 | AA34: 146 | AB34: 157.7 | AC34: 173.5 | AE34: =AC34*1.06 -> 183.91 | AG34: =AE34*1.08 -> 198.6228 | AH34: =AG34 -> 198.6228 | AI34: =AH34*1.05 -> 208.55394 | AJ34: =AI34 -> 208.55394 | AK34: 208.6 | AL34: =AK34*1.06 -> 221.116 | AN34: =AL34 -> 221.116 | AO34: 221.116 | AP34: =AN34-AL34 -> 0 | AQ34: =AO34*1.07 -> 236.59412 | AU34: =AQ34*1.1 -> 260.25353 | AV34: =AU34+(AU34-(AU34*1.15)) -> 221.2155
B35: 29 | E35: 3040 | H35: 2.8 | I35: =ROUNDUP(((AV35*$N$3)+AV35),1) -> 218.5 | K35: 0 | AO35: 218.4 | AQ35: =AO35*1.07 -> 233.688 | AU35: =AQ35*1.1 -> 257.0568 | AV35: =AU35+(AU35-(AU35*1.15)) -> 218.49828
B36: 30 | E36: 3037, 3038 e 3039 | H36: 3 | I36: =ROUNDUP(((AV36*$N$3)+AV36),1) -> 218.5 | K36: 0 | AA36: 146 | AB36: 157.7 | AC36: 173.5 | AE36: =AC36*1.1 -> 190.85 | AG36: =AE36*1.12 -> 213.752 | AH36: =AG36*1.08 -> 230.85216 | AI36: 206 | AJ36: =AI36 -> 206 | AK36: 206 | AL36: =AK36*1.06 -> 218.36 | AN36: =AL36 -> 218.36 | AO36: 218.36 | AP36: =AN36-AL36 -> 0 | AQ36: =AO36*1.07 -> 233.6452 | AU36: =AQ36*1.1 -> 257.00972 | AV36: =AU36+(AU36-(AU36*1.15)) -> 218.45826
B37: 31 | E37: 3043 | H37: 2.5 | I37: =ROUNDUP(((AV37*$N$3)+AV37),1) -> 214.5 | K37: 0 | AN37: =Rolô!I39*1.14 -> 214.434 | AO37: 214.32 | AP37: =AN37-AL37 -> 214.434 | AQ37: =AO37*1.07 -> 229.3224 | AU37: =AQ37*1.1 -> 252.25464 | AV37: =AU37+(AU37-(AU37*1.15)) -> 214.41644
B38: 32 | E38: 3041 | H38: 2.5 | I38: =ROUNDUP(((AV38*$N$3)+AV38),1) -> 174.4 | K38: 0 | AC38: 136.7 | AE38: =AC38*1.06 -> 144.902 | AG38: =AE38*1.08 -> 156.49416 | AH38: =AG38*1.08 -> 169.01369 | AI38: 164.4 | AJ38: =AI38 -> 164.4 | AK38: 164.4 | AL38: =AK38*1.06 -> 174.264 | AN38: =AL38 -> 174.264 | AO38: 174.264 | AP38: =AN38-AL38 -> 0 | AQ38: =AO38*1.07 -> 186.46248 | AU38: =AQ38*1.1 -> 205.10873 | AV38: =AU38+(AU38-(AU38*1.15)) -> 174.34242
B39: 33 | AA39: 115 | AB39: 124.2 | AC39: 136.7 | AE39: =AC39*1.06 -> 144.902 | AG39: =AE39*1.08 -> 156.49416 | AH39: =AG39 -> 156.49416 | AI39: =AH39*1.05 -> 164.31887 | AJ39: =AI39 -> 164.31887 | AQ39: =AO39*1.07 -> 0 | AU39: =AQ39*1.1 -> 0 | AV39: =AU39+(AU39-(AU39*1.15)) -> 0
B40: 34 | E40: 7500 e 7501 | H40: 2.8 | I40: =ROUNDUP(((AV40*$N$3)+AV40),1) -> 212.8 | K40: 0 | AA40: 115 | AB40: 124.2 | AC40: 136.7 | AE40: =AC40*1.06 -> 144.902 | AG40: =AE40*1.12 -> 162.29024 | AH40: =AG40*1.08 -> 175.27346 | AI40: =AH40*1.05 -> 184.03713 | AJ40: =AI40*1.05 -> 193.23899 | AK40: 193.3 | AL40: =AK40*1.1 -> 212.63 | AN40: =AL40 -> 212.63 | AO40: 212.63 | AP40: =AN40-AL40 -> 0 | AQ40: =AO40*1.07 -> 227.5141 | AU40: =AQ40*1.1 -> 250.26551 | AV40: =AU40+(AU40-(AU40*1.15)) -> 212.72568
B41: 35 | E41: 0090, 0096, 7504 e 7508 | H41: 2.8 | I41: =ROUNDUP(((AV41*$N$3)+AV41),1) -> 181 | K41: 0 | AA41: 115 | AB41: 124.2 | AC41: 136.7 | AE41: =AC41*1.06 -> 144.902 | AG41: =AE41*1.08 -> 156.49416 | AH41: =AG41*1.08 -> 169.01369 | AI41: 164.4 | AJ41: =AI41 -> 164.4 | AK41: 164.4 | AL41: =AK41*1.1 -> 180.84 | AN41: =AL41 -> 180.84 | AO41: 180.84 | AP41: =AN41-AL41 -> 0 | AQ41: =AO41*1.07 -> 193.4988 | AU41: =AQ41*1.1 -> 212.84868 | AV41: =AU41+(AU41-(AU41*1.15)) -> 180.92138
B42: 36 | C42: OXFORD BLACKOUT | E42: 0410, 0411 e 0414 | H42: 3 | I42: =ROUNDUP(((AV42*$N$3)+AV42),1) -> 210.5 | K42: 0 | AA42: 151 | AB42: 163.1 | AC42: 179.5 | AE42: =AC42*1.06 -> 190.27 | AG42: =AE42 -> 190.27 | AH42: =AG42*1.05 -> 199.7835 | AI42: =AH42 -> 199.7835 | AJ42: =AI42 -> 199.7835 | AK42: 199.8 | AL42: =AK42*1.06 -> 211.788 | AN42: =Rolô!I42*1.14 -> 189.468 | AO42: 210.33 | AP42: =AN42-AL42 -> -22.32 | AQ42: =AO42*1.07 -> 225.0531 | AU42: =AQ42*1.1 -> 247.55841 | AV42: =AU42+(AU42-(AU42*1.15)) -> 210.42465
...

Sheet Painel
AF1: #NAME?
K2: Página 14 - | L2: =Rolô!$L$2 -> 2026 - v.03 | N2: * DIGITE A PORCENTAGEM PARA MARKUP
B3: CORTINA PAINEL EUROPA | N3: 0
B7: ITEM | C7: COLEÇÃO | E7: COR | H7: VALOR À VISTA (R$)/M² SEM HASTE | J7: VALOR À VISTA (R$)/M² COM HASTE | L7: IPI | AA7: MAI/2016 - SEM HASTE | AB7: MAI/2016 - COM HASTE | AC7: OUT/2017 - SEM HASTE | AD7: OUT/2017 - COM HASTE | AE7: JUN/2018 - SEM HASTE | AF7: JUN/2018 - COM HASTE | AG7: FEV/2020 - SEM HASTE | AH7: FEV/2020 - COM HASTE | AJ7: MAI/2020 - SEM HASTE | AK7: MAI/2020 - COM HASTE | AP7: OUT/2020 - SEM HASTE | AQ7: OUT/2020 - COM HASTE | AR7: MAR/2021 - SEM HASTE | AS7: MAR/2021 - COM HASTE | AU7: JUL/2021 - SEM HASTE | AV7: JUL/2021 - COM HASTE | AW7: JUL/2021 - SEM HASTE | AY7: JUL/2021 - COM HASTE
BD8: 45658 | BF8: 45717
B9: 1 | C9: SCREEN 1% | E9: 0001, 0005, 0006, 1010, 1030 e 1031 | H9: =ROUNDUP(((BF9*$N$3)+BF9),1) -> 157.5 | J9: =ROUNDUP(((BG9*$N$3)+BG9),1) -> 188.9 | L9: 0 | AA9: 103.2 | AB9: 123.8 | AC9: 111.5 | AD9: 133.8 | AE9: =AC9*1.1 -> 122.65 | AF9: =AD9*1.1 -> 147.18 | AG9: =AE9*1.1 -> 134.915 | AH9: =AF9*1.1 -> 161.898 | AJ9: =AG9*1.1 -> 148.4065 | AK9: =AH9*1.1 -> 178.0878 | AP9: =AJ9 -> 148.4065 | AQ9: =AK9 -> 178.0878 | AR9: =AP9 -> 148.4065 | AS9: =AQ9 -> 178.0878 | AU9: =AR9 -> 148.4065 | AV9: =AS9 -> 178.0878 | AW9: 148.5 | AX9: =AW9*1.06 -> 157.41 | AY9: 178.1 | AZ9: =AY9*1.06 -> 188.786 | BB9: =AX9*1.07 -> 168.4287 | BC9: =AZ9*1.07 -> 202.00102 | BD9: =BB9*1.1 -> 185.27157 | BE9: =BC9*1.1 -> 222.20112 | BF9: =BD9+(BD9-(BD9*1.15)) -> 157.48083 | BG9: =BE9+(BE9-(BE9*1.15)) -> 188.87095
B10: 2 | C10: SCREEN FIBER GLASS 1% | E10: 6001 | H10: =ROUNDUP(((BF10*$N$3)+BF10),1) -> 268.7 | J10: =ROUNDUP(((BG10*$N$3)+BG10),1) -> 322.5 | L10: 0 | AA10: 148.6 | AB10: 178.4 | AC10: 160.5 | AD10: 192.7 | AE10: =AC10*1.1 -> 176.55 | AF10: =AD10*1.1 -> 211.97 | AG10: =AE10*1.1 -> 194.205 | AH10: =AF10*1.1 -> 233.167 | AJ10: =AG10*1.15 -> 223.33575 | AK10: =AH10*1.15 -> 268.14205 | AP10: =AJ10*1.08 -> 241.20261 | AQ10: =AK10*1.08 -> 289.59341 | AR10: =AP10*1.05 -> 253.26274 | AS10: =AQ10*1.05 -> 304.07308 | AU10: =AR10 -> 253.26274 | AV10: =AS10 -> 304.07308 | AW10: 253.3 | AX10: =AW10*1.06 -> 268.498 | AY10: 304.1 | AZ10: =AY10*1.06 -> 322.346 | BB10: =AX10*1.07 -> 287.29286 | BC10: =AZ10*1.07 -> 344.91022 | BD10: =BB10*1.1 -> 316.02215 | BE10: =BC10*1.1 -> 379.40124 | BF10: =BD10+(BD10-(BD10*1.15)) -> 268.61882 | BG10: =BE10+(BE10-(BE10*1.15)) -> 322.49106
B11: 3 | C11: SCREEN 3% | E11: 3001, 3002, 3008, 3017, 3060 e 3061 | H11: =ROUNDUP(((BF11*$N$3)+BF11),1) -> 145.9 | J11: =ROUNDUP(((BG11*$N$3)+BG11),1) -> 175.2 | L11: 0 | AA11: 94.5 | AB11: 113.6 | AC11: 102.1 | AD11: 122.7 | AE11: =AC11*1.1 -> 112.31 | AF11: =AD11*1.1 -> 134.97 | AG11: =AE11*1.1 -> 123.541 | AH11: =AF11*1.1 -> 148.467 | AJ11: =AG11*1.08 -> 133.42428 | AK11: =AH11*1.08 -> 160.34436 | AP11: =AJ11 -> 133.42428 | AQ11: =AK11 -> 160.34436 | AR11: =AP11 -> 133.42428 | AS11: =AQ11 -> 160.34436 | AU11: =AR11*1.03 -> 137.42701 | AV11: =AS11*1.03 -> 165.15469 | AW11: 137.5 | AX11: =AW11*1.06 -> 145.75 | AY11: 165.2 | AZ11: =AY11*1.06 -> 175.112 | BB11: =AX11*1.07 -> 155.9525 | BC11: =AZ11*1.07 -> 187.36984 | BD11: =BB11*1.1 -> 171.54775 | BE11: =BC11*1.1 -> 206.10682 | BF11: =BD11+(BD11-(BD11*1.15)) -> 145.81559 | BG11: =BE11+(BE11-(BE11*1.15)) -> 175.1908
B12: 4 | E12: 3009 ao 3011, 3018 e 3019 | H12: =ROUNDUP(((BF12*$N$3)+BF12),1) -> 156.2 | J12: =ROUNDUP(((BG12*$N$3)+BG12),1) -> 187.5 | L12: 0 | AA12: 94.5 | AB12: 113.6 | AC12: 102.1 | AD12: 122.7 | AE12: =AC12*1.1 -> 112.31 | AF12: =AD12*1.1 -> 134.97 | AG12: =AE12*1.1 -> 123.541 | AH12: =AF12*1.1 -> 148.467 | AJ12: =AG12*1.08 -> 133.42428 | AK12: =AH12*1.08 -> 160.34436 | AP12: =AJ12 -> 133.42428 | AQ12: =AK12 -> 160.34436 | AR12: =AP12*1.05 -> 140.09549 | AS12: =AQ12*1.05 -> 168.36158 | AU12: =AR12*1.05 -> 147.10027 | AV12: =AS12*1.05 -> 176.77966 | AW12: 147.2 | AX12: =AW12*1.06 -> 156.032 | AY12: 176.8 | AZ12: =AY12*1.06 -> 187.408 | BB12: =AX12*1.07 -> 166.95424 | BC12: =AZ12*1.07 -> 200.52656 | BD12: =BB12*1.1 -> 183.64966 | BE12: =BC12*1.1 -> 220.57922 | BF12: =BD12+(BD12-(BD12*1.15)) -> 156.10221 | BG12: =BE12+(BE12-(BE12*1.15)) -> 187.49233
B13: 5 | E13: 3012 e 3013 | H13: =ROUNDUP(((BF13*$N$3)+BF13),1) -> 148.6 | J13: =ROUNDUP(((BG13*$N$3)+BG13),1) -> 178.6 | L13: 0 | AU13: 140.1 | AV13: 168.36 | AW13: 140.1 | AX13: =AW13*1.06 -> 148.506 | AY13: 168.4 | AZ13: =AY13*1.06 -> 178.504 | BB13: =AX13*1.07 -> 158.90142 | BC13: =AZ13*1.07 -> 190.99928 | BD13: =BB13*1.1 -> 174.79156 | BE13: =BC13*1.1 -> 210.09921 | BF13: =BD13+(BD13-(BD13*1.15)) -> 148.57283 | BG13: =BE13+(BE13-(BE13*1.15)) -> 178.58433
